Workbook

Sheet Laporan
B1: LAPORAN PENDAPATAN BULANAN
B2: Redjeki Semarang
B3: NO. | C3: TANGGAL | D3: HARI | E3: ROOM | F3: F&B | G3: JUMLAH | H3: TAX | I3: SERVICE | J3: TOTAL | M3: PB1
B4: 1 | C4: 46143 | D4: Jumat | E4: =SUMIF(Input!$D$5:$D$531,C4,Input!$R$5:$R$531) -> 0 | F4: =SUMIF(Input!$D$5:$D$531,C4,Input!$T$5:$T$531) -> 497000 | G4: =E4+F4 -> 497000 | H4: =G4*11% -> 54670 | I4: =G4*1% -> 4970 | J4: =G4+H4+I4 -> 556640 | M4: =+G4*40% -> 198800
B5: 2 | C5: =C4+1 -> 46144 | D5: Sabtu | E5: =SUMIF(Input!$D$5:$D$531,C5,Input!$R$5:$R$531) -> 0 | F5: =SUMIF(Input!$D$5:$D$531,C5,Input!$T$5:$T$531) -> 1299000 | G5: =E5+F5 -> 1299000 | H5: =G5*11% -> 142890 | I5: =G5*1% -> 12990 | J5: =G5+H5+I5 -> 1454880 | M5: =+G5*40% -> 519600
B6: 3 | C6: =C5+1 -> 46145 | D6: Minggu | E6: =SUMIF(Input!$D$5:$D$531,C6,Input!$R$5:$R$531) -> 0 | F6: =SUMIF(Input!$D$5:$D$531,C6,Input!$T$5:$T$531) -> 185000 | G6: =E6+F6 -> 185000 | H6: =G6*11% -> 20350 | I6: =G6*1% -> 1850 | J6: =G6+H6+I6 -> 207200 | M6: =+G6*40% -> 74000
B7: 4 | C7: =C6+1 -> 46146 | D7: Senin | E7: =SUMIF(Input!$D$5:$D$531,C7,Input!$R$5:$R$531) -> 0 | F7: =SUMIF(Input!$D$5:$D$531,C7,Input!$T$5:$T$531) -> 716000 | G7: =E7+F7 -> 716000 | H7: =G7*11% -> 78760 | I7: =G7*1% -> 7160 | J7: =G7+H7+I7 -> 801920 | M7: =+G7*40% -> 286400
B8: 5 | C8: =C7+1 -> 46147 | D8: Selasa | E8: =SUMIF(Input!$D$5:$D$531,C8,Input!$R$5:$R$531) -> 0 | F8: =SUMIF(Input!$D$5:$D$531,C8,Input!$T$5:$T$531) -> 105000 | G8: =E8+F8 -> 105000 | H8: =G8*11% -> 11550 | I8: =G8*1% -> 1050 | J8: =G8+H8+I8 -> 117600 | M8: =+G8*40% -> 42000
B9: 6 | C9: =C8+1 -> 46148 | D9: Rabu | E9: =SUMIF(Input!$D$5:$D$531,C9,Input!$R$5:$R$531) -> 0 | F9: =SUMIF(Input!$D$5:$D$531,C9,Input!$T$5:$T$531) -> 188500 | G9: =E9+F9 -> 188500 | H9: =G9*11% -> 20735 | I9: =G9*1% -> 1885 | J9: =G9+H9+I9 -> 211120 | M9: =+G9*40% -> 75400
B10: 7 | C10: =C9+1 -> 46149 | D10: Kamis | E10: =SUMIF(Input!$D$5:$D$531,C10,Input!$R$5:$R$531) -> 0 | F10: =SUMIF(Input!$D$5:$D$531,C10,Input!$T$5:$T$531) -> 370000 | G10: =E10+F10 -> 370000 | H10: =G10*11% -> 40700 | I10: =G10*1% -> 3700 | J10: =G10+H10+I10 -> 414400 | M10: =+G10*40% -> 148000
B11: 8 | C11: =C10+1 -> 46150 | D11: Jumat | E11: =SUMIF(Input!$D$5:$D$531,C11,Input!$R$5:$R$531) -> 0 | F11: =SUMIF(Input!$D$5:$D$531,C11,Input!$T$5:$T$531) -> 375000 | G11: =E11+F11 -> 375000 | H11: =G11*11% -> 41250 | I11: =G11*1% -> 3750 | J11: =G11+H11+I11 -> 420000 | M11: =+G11*40% -> 150000
B12: 9 | C12: =C11+1 -> 46151 | D12: Sabtu | E12: =SUMIF(Input!$D$5:$D$531,C12,Input!$R$5:$R$531) -> 0 | F12: =SUMIF(Input!$D$5:$D$531,C12,Input!$T$5:$T$531) -> 358000 | G12: =E12+F12 -> 358000 | H12: =G12*11% -> 39380 | I12: =G12*1% -> 3580 | J12: =G12+H12+I12 -> 400960 | M12: =+G12*40% -> 143200
B13: 10 | C13: =C12+1 -> 46152 | D13: Minggu | E13: =SUMIF(Input!$D$5:$D$531,C13,Input!$R$5:$R$531) -> 0 | F13: =SUMIF(Input!$D$5:$D$531,C13,Input!$T$5:$T$531) -> 800000 | G13: =E13+F13 -> 800000 | H13: =G13*11% -> 88000 | I13: =G13*1% -> 8000 | J13: =G13+H13+I13 -> 896000 | M13: =+G13*40% -> 320000
B14: 11 | C14: =C13+1 -> 46153 | D14: Senin | E14: =SUMIF(Input!$D$5:$D$531,C14,Input!$R$5:$R$531) -> 0 | F14: =SUMIF(Input!$D$5:$D$531,C14,Input!$T$5:$T$531) -> 1275000 | G14: =E14+F14 -> 1275000 | H14: =G14*11% -> 140250 | I14: =G14*1% -> 12750 | J14: =G14+H14+I14 -> 1428000 | M14: =+G14*40% -> 510000
B15: 12 | C15: =C14+1 -> 46154 | D15: Selasa | E15: =SUMIF(Input!$D$5:$D$531,C15,Input!$R$5:$R$531) -> 0 | F15: =SUMIF(Input!$D$5:$D$531,C15,Input!$T$5:$T$531) -> 725000 | G15: =E15+F15 -> 725000 | H15: =G15*11% -> 79750 | I15: =G15*1% -> 7250 | J15: =G15+H15+I15 -> 812000 | M15: =+G15*40% -> 290000
B16: 13 | C16: =C15+1 -> 46155 | D16: Rabu | E16: =SUMIF(Input!$D$5:$D$531,C16,Input!$R$5:$R$531) -> 0 | F16: =SUMIF(Input!$D$5:$D$531,C16,Input!$T$5:$T$531) -> 385000 | G16: =E16+F16 -> 385000 | H16: =G16*11% -> 42350 | I16: =G16*1% -> 3850 | J16: =G16+H16+I16 -> 431200 | M16: =+G16*40% -> 154000
... B34: 31 | C34: =C33+1 -> 46173 | D34: Minggu | E34: =SUMIF(Input!$D$5:$D$531,C34,Input!$R$5:$R$531) -> 0 | F34: =SUMIF(Input!$D$5:$D$531,C34,Input!$T$5:$T$531) -> 492000 | G34: =E34+F34 -> 492000 | H34: =G34*11% -> 54120 | I34: =G34*1% -> 4920 | J34: =G34+H34+I34 -> 551040 | M34: =+G34*40% -> 196800
C36: JUMLAH | E36: =SUM(E4:E35) -> 0 | F36: =SUM(F4:F35) -> 15550000 | G36: =SUM(G4:G35) -> 15550000 | H36: =SUM(H4:H35) -> 1710500 | I36: =SUM(I4:I35) -> 155500 | J36: =SUM(J4:J35) -> 17416000 | M36: =SUM(M4:M35) -> 6220000
F39: PB1 | G39: =G36*40% -> 6220000

Sheet Input
C2: 1 | D2: =C2+1 -> 2 | E2: =D2+1 -> 3 | F2: =E2+1 -> 4 | G2: =F2+1 -> 5 | H2: =G2+1 -> 6 | I2: =H2+1 -> 7 | J2: =I2+1 -> 8 | K2: =J2+1 -> 9 | ... U2: =T2+1 -> 19 | V2: =T2+1 -> 19 | W2: =V2+1 -> 20 | X2: =W2+1 -> 21 | Y2: =X2+1 -> 22 | Z2: =Y2+1 -> 23 | AA2: =Z2+1 -> 24 | AB2: =AA2+1 -> 25 | AC2: =AB2+1 -> 26 | AD2: =AC2+1 -> 27 | ... CD2: =CC2+1 -> 79
D3: TANGGAL | E3: PENANGGALAN | H3: BILL | J3: HARI | K3: NAMA | L3: JENIS | M3: HARGA/2 JAM | N3: JAM NORMAL | P3: KELEBIHAN JAM | R3: JUMLAH ROOM | S3: MAKAN/MINUM | U3: TOTAL BILL | W3: MAKANAN | AQ3: MINUMAN | BK3: ROKOK
E4: TANGGAL | F4: BULAN | G4: TAHUN | H4: NOMOR | I4: TANGGAL | N4: QTY | O4: JUMLAH | P4: QTY | Q4: JUMLAH | S4: QTY | T4: JMLH | V4: 1 | W4: NOMOR | X4: NAMA | Y4: QTY | Z4: @ | AA4: JMLH | AB4: NOMOR | AC4: NAMA | AD4: QTY | AE4: @ | AF4: JMLH | AG4: NOMOR | AH4: NAMA | AI4: QTY | AJ4: @ | AK4: JMLH | AL4: NOMOR | AM4: NAMA | AN4: QTY | AO4: @ | AP4: JMLH | AQ4: NOMOR | AR4: NAMA | AS4: QTY | AT4: @ | AU4: JMLH | AV4: NOMOR | AW4: NAMA | AX4: QTY | AY4: @ | AZ4: JMLH | BA4: NOMOR | BB4: NAMA | BC4: QTY | BD4: @ | BE4: JMLH | BF4: NOMOR | BG4: NAMA | BH4: QTY | BI4: @ | BJ4: JMLH | BK4: NOMOR | BL4: NAMA | BM4: QTY | BN4: @ | BO4: JMLH | BP4: NOMOR | BQ4: NAMA | BR4: QTY | BS4: @ | BT4: JMLH | BU4: NOMOR | BV4: NAMA | BW4: QTY | BX4: @ | BY4: JMLH | BZ4: NOMOR | CA4: NAMA | CB4: QTY | CC4: @ | CD4: JMLH
A5: =CONCATENATE(F5,"-",E5,"-20",G5) -> 05-'01-2026 | B5: 1 | C5: 1 | D5: 46143 | E5: '01 | F5: 05 | G5: 26 | H5: =CONCATENATE("RJ","-",E5,F5,G5,"-",B5) -> RJ-'010526-1 | I5: =CONCATENATE(E5,"-",F5,"-20",G5) -> '01-05-2026 | J5: =VLOOKUP(D5,Laporan!$C$4:$D$34,2,0) -> Jumat | L5: Bar | M5: =SUMIF('DATABASE Room'!$B$3:$B$7,L5,'DATABASE Room'!$D$3:$D$7) -> 0 | N5: 1 | O5: =N5*M5 -> 0 | Q5: =P5*M5 -> 0 | R5: =O5+Q5 -> 0 | S5: =SUMIF($W$4:$CD$4,$S$4,W5:CD5) -> 5 | T5: =SUMIF($W$4:$CD$4,$T$4,W5:CD5) -> 145000 | U5: =R5+T5 -> 145000 | W5: 42 | X5: =VLOOKUP(W5,'DATABASE F&B'!$C$3:$F$216,2,0) -> SOJU JINRO ORI | Y5: 1 | Z5: =VLOOKUP(W5,'DATABASE F&B'!$C$3:$F$216,4,0) -> 145000 | AA5: =Y5*Z5 -> 145000 | AC5: =VLOOKUP(AB5,'DATABASE F&B'!$C$3:$F$216,2,0) -> 0 | AD5: 1 | AE5: =VLOOKUP(AB5,'DATABASE F&B'!$C$3:$F$216,4,0) -> 0 | AF5: =AD5*AE5 -> 0 | AH5: =VLOOKUP(AG5,'DATABASE F&B'!$C$3:$F$216,2,0) -> 0 | AI5: 1 | AJ5: =VLOOKUP(AG5,'DATABASE F&B'!$C$3:$F$216,4,0) -> 0 | AK5: =AI5*AJ5 -> 0 | AM5: =VLOOKUP(AL5,'DATABASE F&B'!$C$3:$F$216,2,0) -> 0 | AN5: 1 | AO5: =VLOOKUP(AL5,'DATABASE F&B'!$C$3:$F$216,4,0) -> 0 | AP5: =AN5*AO5 -> 0 | AR5: =VLOOKUP(AQ5,'DATABASE F&B'!$C$3:$F$216,2,0) -> 0 | AS5: 1 | AT5: =VLOOKUP(AQ5,'DATABASE F&B'!$C$3:$F$216,4,0) -> 0 | AU5: =AS5*AT5 -> 0 | AW5: =VLOOKUP(AV5,'DATABASE F&B'!$C$3:$F$216,2,0) -> 0 | AY5: =VLOOKUP(AV5,'DATABASE F&B'!$C$3:$F$216,4,0) -> 0 | AZ5: =AX5*AY5 -> 0 | BB5: =VLOOKUP(BA5,'DATABASE F&B'!$C$3:$F$216,2,0) -> 0 | BD5: =VLOOKUP(BA5,'DATABASE F&B'!$C$3:$F$216,4,0) -> 0 | BE5: =BC5*BD5 -> 0 | BG5: =VLOOKUP(BF5,'DATABASE F&B'!$C$3:$F$216,2,0) -> 0 | BI5: =VLOOKUP(BF5,'DATABASE F&B'!$C$3:$F$216,4,0) -> 0 | BJ5: =BH5*BI5 -> 0 | BL5: =VLOOKUP(BK5,'DATABASE F&B'!$C$3:$F$210,2,0) -> 0 | BN5: =VLOOKUP(BK5,'DATABASE F&B'!$C$3:$F$210,4,0) -> 0 | BO5: =BM5*BN5 -> 0 | BQ5: =VLOOKUP(BP5,'DATABASE F&B'!$C$3:$F$210,2,0) -> 0 | BS5: =VLOOKUP(BP5,'DATABASE F&B'!$C$3:$F$210,4,0) -> 0 | BT5: =BR5*BS5 -> 0 | BV5: =VLOOKUP(BU5,'DATABASE F&B'!$C$3:$F$210,2,0) -> 0 | BX5: =VLOOKUP(BU5,'DATABASE F&B'!$C$3:$F$210,4,0) -> 0 | BY5: =BW5*BX5 -> 0 | CA5: =VLOOKUP(BZ5,'DATABASE F&B'!$C$3:$F$210,2,0) -> 0 | CC5: =VLOOKUP(BZ5,'DATABASE F&B'!$C$3:$F$210,4,0) -> 0 | CD5: =CB5*CC5 -> 0
A6: =CONCATENATE(F6,"-",E6,"-20",G6) -> 05-'01-2026 | B6: =B5+1 -> 2 | C6: =C5+1 -> 2 | D6: 46143 | E6: '01 | F6: 05 | G6: 26 | H6: =CONCATENATE("RJ","-",E6,F6,G6,"-",B6) -> RJ-'010526-2 | I6: =CONCATENATE(E6,"-",F6,"-20",G6) -> '01-05-2026 | J6: =VLOOKUP(D6,Laporan!$C$4:$D$34,2,0) -> Jumat | L6: Bar | M6: =SUMIF('DATABASE Room'!$B$3:$B$7,L6,'DATABASE Room'!$D$3:$D$7) -> 0 | N6: 1 | O6: =N6*M6 -> 0 | Q6: =P6*M6 -> 0 | R6: =O6+Q6 -> 0 | S6: =SUMIF($W$4:$CD$4,$S$4,W6:CD6) -> 5 | T6: =SUMIF($W$4:$CD$4,$T$4,W6:CD6) -> 107000 | U6: =R6+T6 -> 107000 | W6: 95 | X6: =VLOOKUP(W6,'DATABASE F&B'!$C$3:$F$216,2,0) -> MARLBORO RED | Y6: 1 | Z6: =VLOOKUP(W6,'DATABASE F&B'!$C$3:$F$216,4,0) -> 75000 | AA6: =Y6*Z6 -> 75000 | AB6: 20 | AC6: =VLOOKUP(AB6,'DATABASE F&B'!$C$3:$F$216,2,0) -> NASI SAPI ASAP DABU MATAH | AD6: 1 | AE6: =VLOOKUP(AB6,'DATABASE F&B'!$C$3:$F$216,4,0) -> 32000 | AF6: =AD6*AE6 -> 32000 | AH6: =VLOOKUP(AG6,'DATABASE F&B'!$C$3:$F$216,2,0) -> 0 | AI6: 1 | AJ6: =VLOOKUP(AG6,'DATABASE F&B'!$C$3:$F$216,4,0) -> 0 | AK6: =AI6*AJ6 -> 0 | AM6: =VLOOKUP(AL6,'DATABASE F&B'!$C$3:$F$216,2,0) -> 0 | AN6: 1 | AO6: =VLOOKUP(AL6,'DATABASE F&B'!$C$3:$F$216,4,0) -> 0 | AP6: =AN6*AO6 -> 0 | AR6: =VLOOKUP(AQ6,'DATABASE F&B'!$C$3:$F$216,2,0) -> 0 | AS6: 1 | AT6: =VLOOKUP(AQ6,'DATABASE F&B'!$C$3:$F$216,4,0) -> 0 | AU6: =AS6*AT6 -> 0 | AW6: =VLOOKUP(AV6,'DATABASE F&B'!$C$3:$F$216,2,0) -> 0 | AY6: =VLOOKUP(AV6,'DATABASE F&B'!$C$3:$F$216,4,0) -> 0 | AZ6: =AX6*AY6 -> 0 | BB6: =VLOOKUP(BA6,'DATABASE F&B'!$C$3:$F$216,2,0) -> 0 | BD6: =VLOOKUP(BA6,'DATABASE F&B'!$C$3:$F$216,4,0) -> 0 | BE6: =BC6*BD6 -> 0 | BG6: =VLOOKUP(BF6,'DATABASE F&B'!$C$3:$F$216,2,0) -> 0 | BI6: =VLOOKUP(BF6,'DATABASE F&B'!$C$3:$F$216,4,0) -> 0 | BJ6: =BH6*BI6 -> 0 | BL6: =VLOOKUP(BK6,'DATABASE F&B'!$C$3:$F$210,2,0) -> 0 | BN6: =VLOOKUP(BK6,'DATABASE F&B'!$C$3:$F$210,4,0) -> 0 | BO6: =BM6*BN6 -> 0 | BQ6: =VLOOKUP(BP6,'DATABASE F&B'!$C$3:$F$210,2,0) -> 0 | BS6: =VLOOKUP(BP6,'DATABASE F&B'!$C$3:$F$210,4,0) -> 0 | BT6: =BR6*BS6 -> 0 | BV6: =VLOOKUP(BU6,'DATABASE F&B'!$C$3:$F$210,2,0) -> 0 | BX6: =VLOOKUP(BU6,'DATABASE F&B'!$C$3:$F$210,4,0) -> 0 | BY6: =BW6*BX6 -> 0 | CA6: =VLOOKUP(BZ6,'DATABASE F&B'!$C$3:$F$210,2,0) -> 0 | CC6: =VLOOKUP(BZ6,'DATABASE F&B'!$C$3:$F$210,4,0) -> 0 | CD6: =CB6*CC6 -> 0
A7: =CONCATENATE(F7,"-",E7,"-20",G7) -> 05-'01-2026 | B7: =B6+1 -> 3 | C7: =C6+1 -> 3 | D7: 46143 | E7: '01 | F7: 05 | G7: 26 | H7: =CONCATENATE("RJ","-",E7,F7,G7,"-",B7) -> RJ-'010526-3 | I7: =CONCATENATE(E7,"-",F7,"-20",G7) -> '01-05-2026 | J7: =VLOOKUP(D7,Laporan!$C$4:$D$34,2,0) -> Jumat | L7: Bar | M7: =SUMIF('DATABASE Room'!$B$3:$B$7,L7,'DATABASE Room'!$D$3:$D$7) -> 0 | N7: 1 | O7: =N7*M7 -> 0 | Q7: =P7*M7 -> 0 | R7: =O7+Q7 -> 0 | S7: =SUMIF($W$4:$CD$4,$S$4,W7:CD7) -> 5 | T7: =SUMIF($W$4:$CD$4,$T$4,W7:CD7) -> 28000 | U7: =R7+T7 -> 28000 | W7: 15 | X7: =VLOOKUP(W7,'DATABASE F&B'!$C$3:$F$216,2,0) -> CHICKEN SKIN | Y7: 1 | Z7: =VLOOKUP(W7,'DATABASE F&B'!$C$3:$F$216,4,0) -> 28000 | AA7: =Y7*Z7 -> 28000 | AC7: =VLOOKUP(AB7,'DATABASE F&B'!$C$3:$F$216,2,0) -> 0 | AD7: 1 | AE7: =VLOOKUP(AB7,'DATABASE F&B'!$C$3:$F$216,4,0) -> 0 | AF7: =AD7*AE7 -> 0 | AH7: =VLOOKUP(AG7,'DATABASE F&B'!$C$3:$F$216,2,0) -> 0 | AI7: 1 | AJ7: =VLOOKUP(AG7,'DATABASE F&B'!$C$3:$F$216,4,0) -> 0 | AK7: =AI7*AJ7 -> 0 | AM7: =VLOOKUP(AL7,'DATABASE F&B'!$C$3:$F$216,2,0) -> 0 | AN7: 1 | AO7: =VLOOKUP(AL7,'DATABASE F&B'!$C$3:$F$216,4,0) -> 0 | AP7: =AN7*AO7 -> 0 | AR7: =VLOOKUP(AQ7,'DATABASE F&B'!$C$3:$F$216,2,0) -> 0 | AS7: 1 | AT7: =VLOOKUP(AQ7,'DATABASE F&B'!$C$3:$F$216,4,0) -> 0 | AU7: =AS7*AT7 -> 0 | AW7: =VLOOKUP(AV7,'DATABASE F&B'!$C$3:$F$216,2,0) -> 0 | AY7: =VLOOKUP(AV7,'DATABASE F&B'!$C$3:$F$216,4,0) -> 0 | AZ7: =AX7*AY7 -> 0 | BB7: =VLOOKUP(BA7,'DATABASE F&B'!$C$3:$F$216,2,0) -> 0 | BD7: =VLOOKUP(BA7,'DATABASE F&B'!$C$3:$F$216,4,0) -> 0 | BE7: =BC7*BD7 -> 0 | BG7: =VLOOKUP(BF7,'DATABASE F&B'!$C$3:$F$216,2,0) -> 0 | BI7: =VLOOKUP(BF7,'DATABASE F&B'!$C$3:$F$216,4,0) -> 0 | BJ7: =BH7*BI7 -> 0 | BL7: =VLOOKUP(BK7,'DATABASE F&B'!$C$3:$F$210,2,0) -> 0 | BN7: =VLOOKUP(BK7,'DATABASE F&B'!$C$3:$F$210,4,0) -> 0 | BO7: =BM7*BN7 -> 0 | BQ7: =VLOOKUP(BP7,'DATABASE F&B'!$C$3:$F$210,2,0) -> 0 | BS7: =VLOOKUP(BP7,'DATABASE F&B'!$C$3:$F$210,4,0) -> 0 | BT7: =BR7*BS7 -> 0 | BV7: =VLOOKUP(BU7,'DATABASE F&B'!$C$3:$F$210,2,0) -> 0 | BX7: =VLOOKUP(BU7,'DATABASE F&B'!$C$3:$F$210,4,0) -> 0 | BY7: =BW7*BX7 -> 0 | CA7: =VLOOKUP(BZ7,'DATABASE F&B'!$C$3:$F$210,2,0) -> 0 | CC7: =VLOOKUP(BZ7,'DATABASE F&B'!$C$3:$F$210,4,0) -> 0 | CD7: =CB7*CC7 -> 0
A8: =CONCATENATE(F8,"-",E8,"-20",G8) -> 05-'01-2026 | B8: =B7+1 -> 4 | C8: =C7+1 -> 4 | D8: 46143 | E8: '01 | F8: 05 | G8: 26 | H8: =CONCATENATE("RJ","-",E8,F8,G8,"-",B8) -> RJ-'010526-4 | I8: =CONCATENATE(E8,"-",F8,"-20",G8) -> '01-05-2026 | J8: =VLOOKUP(D8,Laporan!$C$4:$D$34,2,0) -> Jumat | L8: Bar | M8: =SUMIF('DATABASE Room'!$B$3:$B$7,L8,'DATABASE Room'!$D$3:$D$7) -> 0 | N8: 1 | O8: =N8*M8 -> 0 | Q8: =P8*M8 -> 0 | R8: =O8+Q8 -> 0 | S8: =SUMIF($W$4:$CD$4,$S$4,W8:CD8) -> 5 | T8: =SUMIF($W$4:$CD$4,$T$4,W8:CD8) -> 36000 | U8: =R8+T8 -> 36000 | W8: 16 | X8: =VLOOKUP(W8,'DATABASE F&B'!$C$3:$F$216,2,0) -> CRISPY CHICKEN WINGS | Y8: 1 | Z8: =VLOOKUP(W8,'DATABASE F&B'!$C$3:$F$216,4,0) -> 36000 | AA8: =Y8*Z8 -> 36000 | AC8: =VLOOKUP(AB8,'DATABASE F&B'!$C$3:$F$216,2,0) -> 0 | AD8: 1 | AE8: =VLOOKUP(AB8,'DATABASE F&B'!$C$3:$F$216,4,0) -> 0 | AF8: =AD8*AE8 -> 0 | AH8: =VLOOKUP(AG8,'DATABASE F&B'!$C$3:$F$216,2,0) -> 0 | AI8: 1 | AJ8: =VLOOKUP(AG8,'DATABASE F&B'!$C$3:$F$216,4,0) -> 0 | AK8: =AI8*AJ8 -> 0 | AM8: =VLOOKUP(AL8,'DATABASE F&B'!$C$3:$F$216,2,0) -> 0 | AN8: 1 | AO8: =VLOOKUP(AL8,'DATABASE F&B'!$C$3:$F$216,4,0) -> 0 | AP8: =AN8*AO8 -> 0 | AR8: =VLOOKUP(AQ8,'DATABASE F&B'!$C$3:$F$216,2,0) -> 0 | AS8: 1 | AT8: =VLOOKUP(AQ8,'DATABASE F&B'!$C$3:$F$216,4,0) -> 0 | AU8: =AS8*AT8 -> 0 | AW8: =VLOOKUP(AV8,'DATABASE F&B'!$C$3:$F$216,2,0) -> 0 | AY8: =VLOOKUP(AV8,'DATABASE F&B'!$C$3:$F$216,4,0) -> 0 | AZ8: =AX8*AY8 -> 0 | BB8: =VLOOKUP(BA8,'DATABASE F&B'!$C$3:$F$216,2,0) -> 0 | BD8: =VLOOKUP(BA8,'DATABASE F&B'!$C$3:$F$216,4,0) -> 0 | BE8: =BC8*BD8 -> 0 | BG8: =VLOOKUP(BF8,'DATABASE F&B'!$C$3:$F$216,2,0) -> 0 | BI8: =VLOOKUP(BF8,'DATABASE F&B'!$C$3:$F$216,4,0) -> 0 | BJ8: =BH8*BI8 -> 0 | BL8: =VLOOKUP(BK8,'DATABASE F&B'!$C$3:$F$210,2,0) -> 0 | BN8: =VLOOKUP(BK8,'DATABASE F&B'!$C$3:$F$210,4,0) -> 0 | BO8: =BM8*BN8 -> 0 | BQ8: =VLOOKUP(BP8,'DATABASE F&B'!$C$3:$F$210,2,0) -> 0 | BS8: =VLOOKUP(BP8,'DATABASE F&B'!$C$3:$F$210,4,0) -> 0 | BT8: =BR8*BS8 -> 0 | BV8: =VLOOKUP(BU8,'DATABASE F&B'!$C$3:$F$210,2,0) -> 0 | BX8: =VLOOKUP(BU8,'DATABASE F&B'!$C$3:$F$210,4,0) -> 0 | BY8: =BW8*BX8 -> 0 | CA8: =VLOOKUP(BZ8,'DATABASE F&B'!$C$3:$F$210,2,0) -> 0 | CC8: =VLOOKUP(BZ8,'DATABASE F&B'!$C$3:$F$210,4,0) -> 0 | CD8: =CB8*CC8 -> 0
A9: =CONCATENATE(F9,"-",E9,"-20",G9) -> 05-'01-2026 | B9: =B8+1 -> 5 | C9: =C8+1 -> 5 | D9: 46143 | E9: '01 | F9: 05 | G9: 26 | H9: =CONCATENATE("RJ","-",E9,F9,G9,"-",B9) -> RJ-'010526-5 | I9: =CONCATENATE(E9,"-",F9,"-20",G9) -> '01-05-2026 | J9: =VLOOKUP(D9,Laporan!$C$4:$D$34,2,0) -> Jumat | L9: Bar | M9: =SUMIF('DATABASE Room'!$B$3:$B$7,L9,'DATABASE Room'!$D$3:$D$7) -> 0 | N9: 1 | O9: =N9*M9 -> 0 | Q9: =P9*M9 -> 0 | R9: =O9+Q9 -> 0 | S9: =SUMIF($W$4:$CD$4,$S$4,W9:CD9) -> 5 | T9: =SUMIF($W$4:$CD$4,$T$4,W9:CD9) -> 36000 | U9: =R9+T9 -> 36000 | W9: 17 | X9: =VLOOKUP(W9,'DATABASE F&B'!$C$3:$F$216,2,0) -> CIRENG | Y9: 1 | Z9: =VLOOKUP(W9,'DATABASE F&B'!$C$3:$F$216,4,0) -> 36000 | AA9: =Y9*Z9 -> 36000 | AC9: =VLOOKUP(AB9,'DATABASE F&B'!$C$3:$F$216,2,0) -> 0 | AD9: 1 | AE9: =VLOOKUP(AB9,'DATABASE F&B'!$C$3:$F$216,4,0) -> 0 | AF9: =AD9*AE9 -> 0 | AH9: =VLOOKUP(AG9,'DATABASE F&B'!$C$3:$F$216,2,0) -> 0 | AI9: 1 | AJ9: =VLOOKUP(AG9,'DATABASE F&B'!$C$3:$F$216,4,0) -> 0 | AK9: =AI9*AJ9 -> 0 | AM9: =VLOOKUP(AL9,'DATABASE F&B'!$C$3:$F$216,2,0) -> 0 | AN9: 1 | AO9: =VLOOKUP(AL9,'DATABASE F&B'!$C$3:$F$216,4,0) -> 0 | AP9: =AN9*AO9 -> 0 | AR9: =VLOOKUP(AQ9,'DATABASE F&B'!$C$3:$F$216,2,0) -> 0 | AS9: 1 | AT9: =VLOOKUP(AQ9,'DATABASE F&B'!$C$3:$F$216,4,0) -> 0 | AU9: =AS9*AT9 -> 0 | AW9: =VLOOKUP(AV9,'DATABASE F&B'!$C$3:$F$216,2,0) -> 0 | AY9: =VLOOKUP(AV9,'DATABASE F&B'!$C$3:$F$216,4,0) -> 0 | AZ9: =AX9*AY9 -> 0 | BB9: =VLOOKUP(BA9,'DATABASE F&B'!$C$3:$F$216,2,0) -> 0 | BD9: =VLOOKUP(BA9,'DATABASE F&B'!$C$3:$F$216,4,0) -> 0 | BE9: =BC9*BD9 -> 0 | BG9: =VLOOKUP(BF9,'DATABASE F&B'!$C$3:$F$216,2,0) -> 0 | BI9: =VLOOKUP(BF9,'DATABASE F&B'!$C$3:$F$216,4,0) -> 0 | BJ9: =BH9*BI9 -> 0 | BL9: =VLOOKUP(BK9,'DATABASE F&B'!$C$3:$F$210,2,0) -> 0 | BN9: =VLOOKUP(BK9,'DATABASE F&B'!$C$3:$F$210,4,0) -> 0 | BO9: =BM9*BN9 -> 0 | BQ9: =VLOOKUP(BP9,'DATABASE F&B'!$C$3:$F$210,2,0) -> 0 | BS9: =VLOOKUP(BP9,'DATABASE F&B'!$C$3:$F$210,4,0) -> 0 | BT9: =BR9*BS9 -> 0 | BV9: =VLOOKUP(BU9,'DATABASE F&B'!$C$3:$F$210,2,0) -> 0 | BX9: =VLOOKUP(BU9,'DATABASE F&B'!$C$3:$F$210,4,0) -> 0 | BY9: =BW9*BX9 -> 0 | CA9: =VLOOKUP(BZ9,'DATABASE F&B'!$C$3:$F$210,2,0) -> 0 | CC9: =VLOOKUP(BZ9,'DATABASE F&B'!$C$3:$F$210,4,0) -> 0 | CD9: =CB9*CC9 -> 0
A10: =CONCATENATE(F10,"-",E10,"-20",G10) -> 05-'01-2026 | B10: =B9+1 -> 6 | C10: =C9+1 -> 6 | D10: 46143 | E10: '01 | F10: 05 | G10: 26 | H10: =CONCATENATE("RJ","-",E10,F10,G10,"-",B10) -> RJ-'010526-6 | I10: =CONCATENATE(E10,"-",F10,"-20",G10) -> '01-05-2026 | J10: =VLOOKUP(D10,Laporan!$C$4:$D$34,2,0) -> Jumat | L10: Bar | M10: =SUMIF('DATABASE Room'!$B$3:$B$7,L10,'DATABASE Room'!$D$3:$D$7) -> 0 | N10: 1 | O10: =N10*M10 -> 0 | Q10: =P10*M10 -> 0 | R10: =O10+Q10 -> 0 | S10: =SUMIF($W$4:$CD$4,$S$4,W10:CD10) -> 5 | T10: =SUMIF($W$4:$CD$4,$T$4,W10:CD10) -> 145000 | U10: =R10+T10 -> 145000 | W10: 43 | X10: =VLOOKUP(W10,'DATABASE F&B'!$C$3:$F$216,2,0) -> SOJU JINRO GREENGRAPE | Y10: 1 | Z10: =VLOOKUP(W10,'DATABASE F&B'!$C$3:$F$216,4,0) -> 145000 | AA10: =Y10*Z10 -> 145000 | AC10: =VLOOKUP(AB10,'DATABASE F&B'!$C$3:$F$216,2,0) -> 0 | AD10: 1 | AE10: =VLOOKUP(AB10,'DATABASE F&B'!$C$3:$F$216,4,0) -> 0 | AF10: =AD10*AE10 -> 0 | AH10: =VLOOKUP(AG10,'DATABASE F&B'!$C$3:$F$216,2,0) -> 0 | AI10: 1 | AJ10: =VLOOKUP(AG10,'DATABASE F&B'!$C$3:$F$216,4,0) -> 0 | AK10: =AI10*AJ10 -> 0 | AM10: =VLOOKUP(AL10,'DATABASE F&B'!$C$3:$F$216,2,0) -> 0 | AN10: 1 | AO10: =VLOOKUP(AL10,'DATABASE F&B'!$C$3:$F$216,4,0) -> 0 | AP10: =AN10*AO10 -> 0 | AR10: =VLOOKUP(AQ10,'DATABASE F&B'!$C$3:$F$216,2,0) -> 0 | AS10: 1 | AT10: =VLOOKUP(AQ10,'DATABASE F&B'!$C$3:$F$216,4,0) -> 0 | AU10: =AS10*AT10 -> 0 | AW10: =VLOOKUP(AV10,'DATABASE F&B'!$C$3:$F$216,2,0) -> 0 | AY10: =VLOOKUP(AV10,'DATABASE F&B'!$C$3:$F$216,4,0) -> 0 | AZ10: =AX10*AY10 -> 0 | BB10: =VLOOKUP(BA10,'DATABASE F&B'!$C$3:$F$216,2,0) -> 0 | BD10: =VLOOKUP(BA10,'DATABASE F&B'!$C$3:$F$216,4,0) -> 0 | BE10: =BC10*BD10 -> 0 | BG10: =VLOOKUP(BF10,'DATABASE F&B'!$C$3:$F$216,2,0) -> 0 | BI10: =VLOOKUP(BF10,'DATABASE F&B'!$C$3:$F$216,4,0) -> 0 | BJ10: =BH10*BI10 -> 0 | BL10: =VLOOKUP(BK10,'DATABASE F&B'!$C$3:$F$210,2,0) -> 0 | BN10: =VLOOKUP(BK10,'DATABASE F&B'!$C$3:$F$210,4,0) -> 0 | BO10: =BM10*BN10 -> 0 | BQ10: =VLOOKUP(BP10,'DATABASE F&B'!$C$3:$F$210,2,0) -> 0 | BS10: =VLOOKUP(BP10,'DATABASE F&B'!$C$3:$F$210,4,0) -> 0 | BT10: =BR10*BS10 -> 0 | BV10: =VLOOKUP(BU10,'DATABASE F&B'!$C$3:$F$210,2,0) -> 0 | BX10: =VLOOKUP(BU10,'DATABASE F&B'!$C$3:$F$210,4,0) -> 0 | BY10: =BW10*BX10 -> 0 | CA10: =VLOOKUP(BZ10,'DATABASE F&B'!$C$3:$F$210,2,0) -> 0 | CC10: =VLOOKUP(BZ10,'DATABASE F&B'!$C$3:$F$210,4,0) -> 0 | CD10: =CB10*CC10 -> 0
A11: =CONCATENATE(F11,"-",E11,"-20",G11) -> 05-'02-2026 | B11: =B10+1 -> 7 | C11: =C10+1 -> 7 | D11: 46144 | E11: '02 | F11: 05 | G11: 26 | H11: =CONCATENATE("RJ","-",E11,F11,G11,"-",B11) -> RJ-'020526-7 | I11: =CONCATENATE(E11,"-",F11,"-20",G11) -> '02-05-2026 | J11: =VLOOKUP(D11,Laporan!$C$4:$D$34,2,0) -> Sabtu | L11: Bar | M11: =SUMIF('DATABASE Room'!$B$3:$B$7,L11,'DATABASE Room'!$D$3:$D$7) -> 0 | N11: 1 | O11: =N11*M11 -> 0 | Q11: =P11*M11 -> 0 | R11: =O11+Q11 -> 0 | S11: =SUMIF($W$4:$CD$4,$S$4,W11:CD11) -> 5 | T11: =SUMIF($W$4:$CD$4,$T$4,W11:CD11) -> 145000 | U11: =R11+T11 -> 145000 | W11: 42 | X11: =VLOOKUP(W11,'DATABASE F&B'!$C$3:$F$216,2,0) -> SOJU JINRO ORI | Y11: 1 | Z11: =VLOOKUP(W11,'DATABASE F&B'!$C$3:$F$216,4,0) -> 145000 | AA11: =Y11*Z11 -> 145000 | AC11: =VLOOKUP(AB11,'DATABASE F&B'!$C$3:$F$216,2,0) -> 0 | AD11: 1 | AE11: =VLOOKUP(AB11,'DATABASE F&B'!$C$3:$F$216,4,0) -> 0 | AF11: =AD11*AE11 -> 0 | AH11: =VLOOKUP(AG11,'DATABASE F&B'!$C$3:$F$216,2,0) -> 0 | AI11: 1 | AJ11: =VLOOKUP(AG11,'DATABASE F&B'!$C$3:$F$216,4,0) -> 0 | AK11: =AI11*AJ11 -> 0 | AM11: =VLOOKUP(AL11,'DATABASE F&B'!$C$3:$F$216,2,0) -> 0 | AN11: 1 | AO11: =VLOOKUP(AL11,'DATABASE F&B'!$C$3:$F$216,4,0) -> 0 | AP11: =AN11*AO11 -> 0 | AR11: =VLOOKUP(AQ11,'DATABASE F&B'!$C$3:$F$216,2,0) -> 0 | AS11: 1 | AT11: =VLOOKUP(AQ11,'DATABASE F&B'!$C$3:$F$216,4,0) -> 0 | AU11: =AS11*AT11 -> 0 | AW11: =VLOOKUP(AV11,'DATABASE F&B'!$C$3:$F$216,2,0) -> 0 | AY11: =VLOOKUP(AV11,'DATABASE F&B'!$C$3:$F$216,4,0) -> 0 | AZ11: =AX11*AY11 -> 0 | BB11: =VLOOKUP(BA11,'DATABASE F&B'!$C$3:$F$216,2,0) -> 0 | BD11: =VLOOKUP(BA11,'DATABASE F&B'!$C$3:$F$216,4,0) -> 0 | BE11: =BC11*BD11 -> 0 | BG11: =VLOOKUP(BF11,'DATABASE F&B'!$C$3:$F$216,2,0) -> 0 | BI11: =VLOOKUP(BF11,'DATABASE F&B'!$C$3:$F$216,4,0) -> 0 | BJ11: =BH11*BI11 -> 0 | BL11: =VLOOKUP(BK11,'DATABASE F&B'!$C$3:$F$210,2,0) -> 0 | BN11: =VLOOKUP(BK11,'DATABASE F&B'!$C$3:$F$210,4,0) -> 0 | BO11: =BM11*BN11 -> 0 | BQ11: =VLOOKUP(BP11,'DATABASE F&B'!$C$3:$F$210,2,0) -> 0 | BS11: =VLOOKUP(BP11,'DATABASE F&B'!$C$3:$F$210,4,0) -> 0 | BT11: =BR11*BS11 -> 0 | BV11: =VLOOKUP(BU11,'DATABASE F&B'!$C$3:$F$210,2,0) -> 0 | BX11: =VLOOKUP(BU11,'DATABASE F&B'!$C$3:$F$210,4,0) -> 0 | BY11: =BW11*BX11 -> 0 | CA11: =VLOOKUP(BZ11,'DATABASE F&B'!$C$3:$F$210,2,0) -> 0 | CC11: =VLOOKUP(BZ11,'DATABASE F&B'!$C$3:$F$210,4,0) -> 0 | CD11: =CB11*CC11 -> 0
A12: =CONCATENATE(F12,"-",E12,"-20",G12) -> 05-'02-2026 | B12: =B11+1 -> 8 | C12: =C11+1 -> 8 | D12: 46144 | E12: '02 | F12: 05 | G12: 26 | H12: =CONCATENATE("RJ","-",E12,F12,G12,"-",B12) -> RJ-'020526-8 | I12: =CONCATENATE(E12,"-",F12,"-20",G12) -> '02-05-2026 | J12: =VLOOKUP(D12,Laporan!$C$4:$D$34,2,0) -> Sabtu | L12: Bar | M12: =SUMIF('DATABASE Room'!$B$3:$B$7,L12,'DATABASE Room'!$D$3:$D$7) -> 0 | N12: 1 | O12: =N12*M12 -> 0 | Q12: =P12*M12 -> 0 | R12: =O12+Q12 -> 0 | S12: =SUMIF($W$4:$CD$4,$S$4,W12:CD12) -> 5 | T12: =SUMIF($W$4:$CD$4,$T$4,W12:CD12) -> 200000 | U12: =R12+T12 -> 200000 | W12: 44 | X12: =VLOOKUP(W12,'DATABASE F&B'!$C$3:$F$216,2,0) -> SOJU JINRO PEACH | Y12: 1 | Z12: =VLOOKUP(W12,'DATABASE F&B'!$C$3:$F$216,4,0) -> 145000 | AA12: =Y12*Z12 -> 145000 | AB12: 99 | AC12: =VLOOKUP(AB12,'DATABASE F&B'!$C$3:$F$216,2,0) -> SAMPOERNA MENTOL | AD12: 1 | AE12: =VLOOKUP(AB12,'DATABASE F&B'!$C$3:$F$216,4,0) -> 55000 | AF12: =AD12*AE12 -> 55000 | AH12: =VLOOKUP(AG12,'DATABASE F&B'!$C$3:$F$216,2,0) -> 0 | AI12: 1 | AJ12: =VLOOKUP(AG12,'DATABASE F&B'!$C$3:$F$216,4,0) -> 0 | AK12: =AI12*AJ12 -> 0 | AM12: =VLOOKUP(AL12,'DATABASE F&B'!$C$3:$F$216,2,0) -> 0 | AN12: 1 | AO12: =VLOOKUP(AL12,'DATABASE F&B'!$C$3:$F$216,4,0) -> 0 | AP12: =AN12*AO12 -> 0 | AR12: =VLOOKUP(AQ12,'DATABASE F&B'!$C$3:$F$216,2,0) -> 0 | AS12: 1 | AT12: =VLOOKUP(AQ12,'DATABASE F&B'!$C$3:$F$216,4,0) -> 0 | AU12: =AS12*AT12 -> 0 | AW12: =VLOOKUP(AV12,'DATABASE F&B'!$C$3:$F$216,2,0) -> 0 | AY12: =VLOOKUP(AV12,'DATABASE F&B'!$C$3:$F$216,4,0) -> 0 | AZ12: =AX12*AY12 -> 0 | BB12: =VLOOKUP(BA12,'DATABASE F&B'!$C$3:$F$216,2,0) -> 0 | BD12: =VLOOKUP(BA12,'DATABASE F&B'!$C$3:$F$216,4,0) -> 0 | BE12: =BC12*BD12 -> 0 | BG12: =VLOOKUP(BF12,'DATABASE F&B'!$C$3:$F$216,2,0) -> 0 | BI12: =VLOOKUP(BF12,'DATABASE F&B'!$C$3:$F$216,4,0) -> 0 | BJ12: =BH12*BI12 -> 0 | BL12: =VLOOKUP(BK12,'DATABASE F&B'!$C$3:$F$210,2,0) -> 0 | BN12: =VLOOKUP(BK12,'DATABASE F&B'!$C$3:$F$210,4,0) -> 0 | BO12: =BM12*BN12 -> 0 | BQ12: =VLOOKUP(BP12,'DATABASE F&B'!$C$3:$F$210,2,0) -> 0 | BS12: =VLOOKUP(BP12,'DATABASE F&B'!$C$3:$F$210,4,0) -> 0 | BT12: =BR12*BS12 -> 0 | BV12: =VLOOKUP(BU12,'DATABASE F&B'!$C$3:$F$210,2,0) -> 0 | BX12: =VLOOKUP(BU12,'DATABASE F&B'!$C$3:$F$210,4,0) -> 0 | BY12: =BW12*BX12 -> 0 | CA12: =VLOOKUP(BZ12,'DATABASE F&B'!$C$3:$F$210,2,0) -> 0 | CC12: =VLOOKUP(BZ12,'DATABASE F&B'!$C$3:$F$210,4,0) -> 0 | CD12: =CB12*CC12 -> 0
A13: =CONCATENATE(F13,"-",E13,"-20",G13) -> 05-'02-2026 | B13: =B12+1 -> 9 | C13: =C12+1 -> 9 | D13: 46144 | E13: '02 | F13: 05 | G13: 26 | H13: =CONCATENATE("RJ","-",E13,F13,G13,"-",B13) -> RJ-'020526-9 | I13: =CONCATENATE(E13,"-",F13,"-20",G13) -> '02-05-2026 | J13: =VLOOKUP(D13,Laporan!$C$4:$D$34,2,0) -> Sabtu | L13: Bar | M13: =SUMIF('DATABASE Room'!$B$3:$B$7,L13,'DATABASE Room'!$D$3:$D$7) -> 0 | N13: 1 | O13: =N13*M13 -> 0 | Q13: =P13*M13 -> 0 | R13: =O13+Q13 -> 0 | S13: =SUMIF($W$4:$CD$4,$S$4,W13:CD13) -> 5 | T13: =SUMIF($W$4:$CD$4,$T$4,W13:CD13) -> 825000 | U13: =R13+T13 -> 825000 | W13: 119 | X13: =VLOOKUP(W13,'DATABASE F&B'!$C$3:$F$216,2,0) -> JACK DANIELS NO 7 | Y13: 1 | Z13: =VLOOKUP(W13,'DATABASE F&B'!$C$3:$F$216,4,0) -> 825000 | AA13: =Y13*Z13 -> 825000 | AC13: =VLOOKUP(AB13,'DATABASE F&B'!$C$3:$F$216,2,0) -> 0 | AD13: 1 | AE13: =VLOOKUP(AB13,'DATABASE F&B'!$C$3:$F$216,4,0) -> 0 | AF13: =AD13*AE13 -> 0 | AH13: =VLOOKUP(AG13,'DATABASE F&B'!$C$3:$F$216,2,0) -> 0 | AI13: 1 | AJ13: =VLOOKUP(AG13,'DATABASE F&B'!$C$3:$F$216,4,0) -> 0 | AK13: =AI13*AJ13 -> 0 | AM13: =VLOOKUP(AL13,'DATABASE F&B'!$C$3:$F$216,2,0) -> 0 | AN13: 1 | AO13: =VLOOKUP(AL13,'DATABASE F&B'!$C$3:$F$216,4,0) -> 0 | AP13: =AN13*AO13 -> 0 | AR13: =VLOOKUP(AQ13,'DATABASE F&B'!$C$3:$F$216,2,0) -> 0 | AS13: 1 | AT13: =VLOOKUP(AQ13,'DATABASE F&B'!$C$3:$F$216,4,0) -> 0 | AU13: =AS13*AT13 -> 0 | AW13: =VLOOKUP(AV13,'DATABASE F&B'!$C$3:$F$216,2,0) -> 0 | AY13: =VLOOKUP(AV13,'DATABASE F&B'!$C$3:$F$216,4,0) -> 0 | AZ13: =AX13*AY13 -> 0 | BB13: =VLOOKUP(BA13,'DATABASE F&B'!$C$3:$F$216,2,0) -> 0 | BD13: =VLOOKUP(BA13,'DATABASE F&B'!$C$3:$F$216,4,0) -> 0 | BE13: =BC13*BD13 -> 0 | BG13: =VLOOKUP(BF13,'DATABASE F&B'!$C$3:$F$216,2,0) -> 0 | BI13: =VLOOKUP(BF13,'DATABASE F&B'!$C$3:$F$216,4,0) -> 0 | BJ13: =BH13*BI13 -> 0 | BL13: =VLOOKUP(BK13,'DATABASE F&B'!$C$3:$F$210,2,0) -> 0 | BN13: =VLOOKUP(BK13,'DATABASE F&B'!$C$3:$F$210,4,0) -> 0 | BO13: =BM13*BN13 -> 0 | BQ13: =VLOOKUP(BP13,'DATABASE F&B'!$C$3:$F$210,2,0) -> 0 | BS13: =VLOOKUP(BP13,'DATABASE F&B'!$C$3:$F$210,4,0) -> 0 | BT13: =BR13*BS13 -> 0 | BV13: =VLOOKUP(BU13,'DATABASE F&B'!$C$3:$F$210,2,0) -> 0 | BX13: =VLOOKUP(BU13,'DATABASE F&B'!$C$3:$F$210,4,0) -> 0 | BY13: =BW13*BX13 -> 0 | CA13: =VLOOKUP(BZ13,'DATABASE F&B'!$C$3:$F$210,2,0) -> 0 | CC13: =VLOOKUP(BZ13,'DATABASE F&B'!$C$3:$F$210,4,0) -> 0 | CD13: =CB13*CC13 -> 0
A14: =CONCATENATE(F14,"-",E14,"-20",G14) -> 05-'02-2026 | B14: =B13+1 -> 10 | C14: =C13+1 -> 10 | D14: 46144 | E14: '02 | F14: 05 | G14: 26 | H14: =CONCATENATE("RJ","-",E14,F14,G14,"-",B14) -> RJ-'020526-10 | I14: =CONCATENATE(E14,"-",F14,"-20",G14) -> '02-05-2026 | J14: =VLOOKUP(D14,Laporan!$C$4:$D$34,2,0) -> Sabtu | L14: Bar | M14: =SUMIF('DATABASE Room'!$B$3:$B$7,L14,'DATABASE Room'!$D$3:$D$7) -> 0 | N14: 1 | O14: =N14*M14 -> 0 | Q14: =P14*M14 -> 0 | R14: =O14+Q14 -> 0 | S14: =SUMIF($W$4:$CD$4,$S$4,W14:CD14) -> 5 | T14: =SUMIF($W$4:$CD$4,$T$4,W14:CD14) -> 32000 | U14: =R14+T14 -> 32000 | W14: 22 | X14: =VLOOKUP(W14,'DATABASE F&B'!$C$3:$F$216,2,0) -> PERI PERI CHICKEN RICE | Y14: 1 | Z14: =VLOOKUP(W14,'DATABASE F&B'!$C$3:$F$216,4,0) -> 32000 | AA14: =Y14*Z14 -> 32000 | AC14: =VLOOKUP(AB14,'DATABASE F&B'!$C$3:$F$216,2,0) -> 0 | AD14: 1 | AE14: =VLOOKUP(AB14,'DATABASE F&B'!$C$3:$F$216,4,0) -> 0 | AF14: =AD14*AE14 -> 0 | AH14: =VLOOKUP(AG14,'DATABASE F&B'!$C$3:$F$216,2,0) -> 0 | AI14: 1 | AJ14: =VLOOKUP(AG14,'DATABASE F&B'!$C$3:$F$216,4,0) -> 0 | AK14: =AI14*AJ14 -> 0 | AM14: =VLOOKUP(AL14,'DATABASE F&B'!$C$3:$F$216,2,0) -> 0 | AN14: 1 | AO14: =VLOOKUP(AL14,'DATABASE F&B'!$C$3:$F$216,4,0) -> 0 | AP14: =AN14*AO14 -> 0 | AR14: =VLOOKUP(AQ14,'DATABASE F&B'!$C$3:$F$216,2,0) -> 0 | AS14: 1 | AT14: =VLOOKUP(AQ14,'DATABASE F&B'!$C$3:$F$216,4,0) -> 0 | AU14: =AS14*AT14 -> 0 | AW14: =VLOOKUP(AV14,'DATABASE F&B'!$C$3:$F$216,2,0) -> 0 | AY14: =VLOOKUP(AV14,'DATABASE F&B'!$C$3:$F$216,4,0) -> 0 | AZ14: =AX14*AY14 -> 0 | BB14: =VLOOKUP(BA14,'DATABASE F&B'!$C$3:$F$216,2,0) -> 0 | BD14: =VLOOKUP(BA14,'DATABASE F&B'!$C$3:$F$216,4,0) -> 0 | BE14: =BC14*BD14 -> 0 | BG14: =VLOOKUP(BF14,'DATABASE F&B'!$C$3:$F$216,2,0) -> 0 | BI14: =VLOOKUP(BF14,'DATABASE F&B'!$C$3:$F$216,4,0) -> 0 | BJ14: =BH14*BI14 -> 0 | BL14: =VLOOKUP(BK14,'DATABASE F&B'!$C$3:$F$210,2,0) -> 0 | BN14: =VLOOKUP(BK14,'DATABASE F&B'!$C$3:$F$210,4,0) -> 0 | BO14: =BM14*BN14 -> 0 | BQ14: =VLOOKUP(BP14,'DATABASE F&B'!$C$3:$F$210,2,0) -> 0 | BS14: =VLOOKUP(BP14,'DATABASE F&B'!$C$3:$F$210,4,0) -> 0 | BT14: =BR14*BS14 -> 0 | BV14: =VLOOKUP(BU14,'DATABASE F&B'!$C$3:$F$210,2,0) -> 0 | BX14: =VLOOKUP(BU14,'DATABASE F&B'!$C$3:$F$210,4,0) -> 0 | BY14: =BW14*BX14 -> 0 | CA14: =VLOOKUP(BZ14,'DATABASE F&B'!$C$3:$F$210,2,0) -> 0 | CC14: =VLOOKUP(BZ14,'DATABASE F&B'!$C$3:$F$210,4,0) -> 0 | CD14: =CB14*CC14 -> 0
A15: =CONCATENATE(F15,"-",E15,"-20",G15) -> 05-'02-2026 | B15: =B14+1 -> 11 | C15: =C14+1 -> 11 | D15: 46144 | E15: '02 | F15: 05 | G15: 26 | H15: =CONCATENATE("RJ","-",E15,F15,G15,"-",B15) -> RJ-'020526-11 | I15: =CONCATENATE(E15,"-",F15,"-20",G15) -> '02-05-2026 | J15: =VLOOKUP(D15,Laporan!$C$4:$D$34,2,0) -> Sabtu | L15: Bar | M15: =SUMIF('DATABASE Room'!$B$3:$B$7,L15,'DATABASE Room'!$D$3:$D$7) -> 0 | N15: 1 | O15: =N15*M15 -> 0 | Q15: =P15*M15 -> 0 | R15: =O15+Q15 -> 0 | S15: =SUMIF($W$4:$CD$4,$S$4,W15:CD15) -> 5 | T15: =SUMIF($W$4:$CD$4,$T$4,W15:CD15) -> 32000 | U15: =R15+T15 -> 32000 | W15: 23 | X15: =VLOOKUP(W15,'DATABASE F&B'!$C$3:$F$216,2,0) -> NASI GORENG TUNA SAMBAL IJO | Y15: 1 | Z15: =VLOOKUP(W15,'DATABASE F&B'!$C$3:$F$216,4,0) -> 32000 | AA15: =Y15*Z15 -> 32000 | AC15: =VLOOKUP(AB15,'DATABASE F&B'!$C$3:$F$216,2,0) -> 0 | AD15: 1 | AE15: =VLOOKUP(AB15,'DATABASE F&B'!$C$3:$F$216,4,0) -> 0 | AF15: =AD15*AE15 -> 0 | AH15: =VLOOKUP(AG15,'DATABASE F&B'!$C$3:$F$216,2,0) -> 0 | AI15: 1 | AJ15: =VLOOKUP(AG15,'DATABASE F&B'!$C$3:$F$216,4,0) -> 0 | AK15: =AI15*AJ15 -> 0 | AM15: =VLOOKUP(AL15,'DATABASE F&B'!$C$3:$F$216,2,0) -> 0 | AN15: 1 | AO15: =VLOOKUP(AL15,'DATABASE F&B'!$C$3:$F$216,4,0) -> 0 | AP15: =AN15*AO15 -> 0 | AR15: =VLOOKUP(AQ15,'DATABASE F&B'!$C$3:$F$216,2,0) -> 0 | AS15: 1 | AT15: =VLOOKUP(AQ15,'DATABASE F&B'!$C$3:$F$216,4,0) -> 0 | AU15: =AS15*AT15 -> 0 | AW15: =VLOOKUP(AV15,'DATABASE F&B'!$C$3:$F$216,2,0) -> 0 | AY15: =VLOOKUP(AV15,'DATABASE F&B'!$C$3:$F$216,4,0) -> 0 | AZ15: =AX15*AY15 -> 0 | BB15: =VLOOKUP(BA15,'DATABASE F&B'!$C$3:$F$216,2,0) -> 0 | BD15: =VLOOKUP(BA15,'DATABASE F&B'!$C$3:$F$216,4,0) -> 0 | BE15: =BC15*BD15 -> 0 | BG15: =VLOOKUP(BF15,'DATABASE F&B'!$C$3:$F$216,2,0) -> 0 | BI15: =VLOOKUP(BF15,'DATABASE F&B'!$C$3:$F$216,4,0) -> 0 | BJ15: =BH15*BI15 -> 0 | BL15: =VLOOKUP(BK15,'DATABASE F&B'!$C$3:$F$210,2,0) -> 0 | BN15: =VLOOKUP(BK15,'DATABASE F&B'!$C$3:$F$210,4,0) -> 0 | BO15: =BM15*BN15 -> 0 | BQ15: =VLOOKUP(BP15,'DATABASE F&B'!$C$3:$F$210,2,0) -> 0 | BS15: =VLOOKUP(BP15,'DATABASE F&B'!$C$3:$F$210,4,0) -> 0 | BT15: =BR15*BS15 -> 0 | BV15: =VLOOKUP(BU15,'DATABASE F&B'!$C$3:$F$210,2,0) -> 0 | BX15: =VLOOKUP(BU15,'DATABASE F&B'!$C$3:$F$210,4,0) -> 0 | BY15: =BW15*BX15 -> 0 | CA15: =VLOOKUP(BZ15,'DATABASE F&B'!$C$3:$F$210,2,0) -> 0 | CC15: =VLOOKUP(BZ15,'DATABASE F&B'!$C$3:$F$210,4,0) -> 0 | CD15: =CB15*CC15 -> 0
A16: =CONCATENATE(F16,"-",E16,"-20",G16) -> 05-'02-2026 | B16: =B15+1 -> 12 | C16: =C15+1 -> 12 | D16: 46144 | E16: '02 | F16: 05 | G16: 26 | H16: =CONCATENATE("RJ","-",E16,F16,G16,"-",B16) -> RJ-'020526-12 | I16: =CONCATENATE(E16,"-",F16,"-20",G16) -> '02-05-2026 | J16: =VLOOKUP(D16,Laporan!$C$4:$D$34,2,0) -> Sabtu | L16: Bar | M16: =SUMIF('DATABASE Room'!$B$3:$B$7,L16,'DATABASE Room'!$D$3:$D$7) -> 0 | N16: 1 | O16: =N16*M16 -> 0 | Q16: =P16*M16 -> 0 | R16: =O16+Q16 -> 0 | S16: =SUMIF($W$4:$CD$4,$S$4,W16:CD16) -> 5 | T16: =SUMIF($W$4:$CD$4,$T$4,W16:CD16) -> 57000 | U16: =R16+T16 -> 57000 | W16: 24 | X16: =VLOOKUP(W16,'DATABASE F&B'!$C$3:$F$216,2,0) -> KATSU OMURICE | Y16: 1 | Z16: =VLOOKUP(W16,'DATABASE F&B'!$C$3:$F$216,4,0) -> 35000 | AA16: =Y16*Z16 -> 35000 | AB16: 8 | AC16: =VLOOKUP(AB16,'DATABASE F&B'!$C$3:$F$216,2,0) -> MACARONI PEDES | AD16: 1 | AE16: =VLOOKUP(AB16,'DATABASE F&B'!$C$3:$F$216,4,0) -> 22000 | AF16: =AD16*AE16 -> 22000 | AH16: =VLOOKUP(AG16,'DATABASE F&B'!$C$3:$F$216,2,0) -> 0 | AI16: 1 | AJ16: =VLOOKUP(AG16,'DATABASE F&B'!$C$3:$F$216,4,0) -> 0 | AK16: =AI16*AJ16 -> 0 | AM16: =VLOOKUP(AL16,'DATABASE F&B'!$C$3:$F$216,2,0) -> 0 | AN16: 1 | AO16: =VLOOKUP(AL16,'DATABASE F&B'!$C$3:$F$216,4,0) -> 0 | AP16: =AN16*AO16 -> 0 | AR16: =VLOOKUP(AQ16,'DATABASE F&B'!$C$3:$F$216,2,0) -> 0 | AS16: 1 | AT16: =VLOOKUP(AQ16,'DATABASE F&B'!$C$3:$F$216,4,0) -> 0 | AU16: =AS16*AT16 -> 0 | AW16: =VLOOKUP(AV16,'DATABASE F&B'!$C$3:$F$216,2,0) -> 0 | AY16: =VLOOKUP(AV16,'DATABASE F&B'!$C$3:$F$216,4,0) -> 0 | AZ16: =AX16*AY16 -> 0 | BB16: =VLOOKUP(BA16,'DATABASE F&B'!$C$3:$F$216,2,0) -> 0 | BD16: =VLOOKUP(BA16,'DATABASE F&B'!$C$3:$F$216,4,0) -> 0 | BE16: =BC16*BD16 -> 0 | BG16: =VLOOKUP(BF16,'DATABASE F&B'!$C$3:$F$216,2,0) -> 0 | BI16: =VLOOKUP(BF16,'DATABASE F&B'!$C$3:$F$216,4,0) -> 0 | BJ16: =BH16*BI16 -> 0 | BL16: =VLOOKUP(BK16,'DATABASE F&B'!$C$3:$F$210,2,0) -> 0 | BN16: =VLOOKUP(BK16,'DATABASE F&B'!$C$3:$F$210,4,0) -> 0 | BO16: =BM16*BN16 -> 0 | BQ16: =VLOOKUP(BP16,'DATABASE F&B'!$C$3:$F$210,2,0) -> 0 | BS16: =VLOOKUP(BP16,'DATABASE F&B'!$C$3:$F$210,4,0) -> 0 | BT16: =BR16*BS16 -> 0 | BV16: =VLOOKUP(BU16,'DATABASE F&B'!$C$3:$F$210,2,0) -> 0 | BX16: =VLOOKUP(BU16,'DATABASE F&B'!$C$3:$F$210,4,0) -> 0 | BY16: =BW16*BX16 -> 0 | CA16: =VLOOKUP(BZ16,'DATABASE F&B'!$C$3:$F$210,2,0) -> 0 | CC16: =VLOOKUP(BZ16,'DATABASE F&B'!$C$3:$F$210,4,0) -> 0 | CD16: =CB16*CC16 -> 0
A17: =CONCATENATE(F17,"-",E17,"-20",G17) -> 05-'02-2026 | B17: =B16+1 -> 13 | C17: =C16+1 -> 13 | D17: 46144 | E17: '02 | F17: 05 | G17: 26 | H17: =CONCATENATE("RJ","-",E17,F17,G17,"-",B17) -> RJ-'020526-13 | I17: =CONCATENATE(E17,"-",F17,"-20",G17) -> '02-05-2026 | J17: =VLOOKUP(D17,Laporan!$C$4:$D$34,2,0) -> Sabtu | L17: Bar | M17: =SUMIF('DATABASE Room'!$B$3:$B$7,L17,'DATABASE Room'!$D$3:$D$7) -> 0 | N17: 1 | O17: =N17*M17 -> 0 | Q17: =P17*M17 -> 0 | R17: =O17+Q17 -> 0 | S17: =SUMIF($W$4:$CD$4,$S$4,W17:CD17) -> 5 | T17: =SUMIF($W$4:$CD$4,$T$4,W17:CD17) -> 8000 | U17: =R17+T17 -> 8000 | W17: 45 | X17: =VLOOKUP(W17,'DATABASE F&B'!$C$3:$F$216,2,0) -> LE MINERAL 330ML | Y17: 1 | Z17: =VLOOKUP(W17,'DATABASE F&B'!$C$3:$F$216,4,0) -> 8000 | AA17: =Y17*Z17 -> 8000 | AC17: =VLOOKUP(AB17,'DATABASE F&B'!$C$3:$F$216,2,0) -> 0 | AD17: 1 | AE17: =VLOOKUP(AB17,'DATABASE F&B'!$C$3:$F$216,4,0) -> 0 | AF17: =AD17*AE17 -> 0 | AH17: =VLOOKUP(AG17,'DATABASE F&B'!$C$3:$F$216,2,0) -> 0 | AI17: 1 | AJ17: =VLOOKUP(AG17,'DATABASE F&B'!$C$3:$F$216,4,0) -> 0 | AK17: =AI17*AJ17 -> 0 | AM17: =VLOOKUP(AL17,'DATABASE F&B'!$C$3:$F$216,2,0) -> 0 | AN17: 1 | AO17: =VLOOKUP(AL17,'DATABASE F&B'!$C$3:$F$216,4,0) -> 0 | AP17: =AN17*AO17 -> 0 | AR17: =VLOOKUP(AQ17,'DATABASE F&B'!$C$3:$F$216,2,0) -> 0 | AS17: 1 | AT17: =VLOOKUP(AQ17,'DATABASE F&B'!$C$3:$F$216,4,0) -> 0 | AU17: =AS17*AT17 -> 0 | AW17: =VLOOKUP(AV17,'DATABASE F&B'!$C$3:$F$216,2,0) -> 0 | AY17: =VLOOKUP(AV17,'DATABASE F&B'!$C$3:$F$216,4,0) -> 0 | AZ17: =AX17*AY17 -> 0 | BB17: =VLOOKUP(BA17,'DATABASE F&B'!$C$3:$F$216,2,0) -> 0 | BD17: =VLOOKUP(BA17,'DATABASE F&B'!$C$3:$F$216,4,0) -> 0 | BE17: =BC17*BD17 -> 0 | BG17: =VLOOKUP(BF17,'DATABASE F&B'!$C$3:$F$216,2,0) -> 0 | BI17: =VLOOKUP(BF17,'DATABASE F&B'!$C$3:$F$216,4,0) -> 0 | BJ17: =BH17*BI17 -> 0 | BL17: =VLOOKUP(BK17,'DATABASE F&B'!$C$3:$F$210,2,0) -> 0 | BN17: =VLOOKUP(BK17,'DATABASE F&B'!$C$3:$F$210,4,0) -> 0 | BO17: =BM17*BN17 -> 0 | BQ17: =VLOOKUP(BP17,'DATABASE F&B'!$C$3:$F$210,2,0) -> 0 | BS17: =VLOOKUP(BP17,'DATABASE F&B'!$C$3:$F$210,4,0) -> 0 | BT17: =BR17*BS17 -> 0 | BV17: =VLOOKUP(BU17,'DATABASE F&B'!$C$3:$F$210,2,0) -> 0 | BX17: =VLOOKUP(BU17,'DATABASE F&B'!$C$3:$F$210,4,0) -> 0 | BY17: =BW17*BX17 -> 0 | CA17: =VLOOKUP(BZ17,'DATABASE F&B'!$C$3:$F$210,2,0) -> 0 | CC17: =VLOOKUP(BZ17,'DATABASE F&B'!$C$3:$F$210,4,0) -> 0 | CD17: =CB17*CC17 -> 0
A18: =CONCATENATE(F18,"-",E18,"-20",G18) -> 05-'03-2026 | B18: =B17+1 -> 14 | C18: =C17+1 -> 14 | D18: 46145 | E18: '03 | F18: 05 | G18: 26 | H18: =CONCATENATE("RJ","-",E18,F18,G18,"-",B18) -> RJ-'030526-14 | I18: =CONCATENATE(E18,"-",F18,"-20",G18) -> '03-05-2026 | J18: =VLOOKUP(D18,Laporan!$C$4:$D$34,2,0) -> Minggu | L18: Bar | M18: =SUMIF('DATABASE Room'!$B$3:$B$7,L18,'DATABASE Room'!$D$3:$D$7) -> 0 | N18: 1 | O18: =N18*M18 -> 0 | Q18: =P18*M18 -> 0 | R18: =O18+Q18 -> 0 | S18: =SUMIF($W$4:$CD$4,$S$4,W18:CD18) -> 5 | T18: =SUMIF($W$4:$CD$4,$T$4,W18:CD18) -> 15000 | U18: =R18+T18 -> 15000 | W18: 46 | X18: =VLOOKUP(W18,'DATABASE F&B'!$C$3:$F$216,2,0) -> TEH PUCUK HARUM 350ML | Y18: 1 | Z18: =VLOOKUP(W18,'DATABASE F&B'!$C$3:$F$216,4,0) -> 15000 | AA18: =Y18*Z18 -> 15000 | AC18: =VLOOKUP(AB18,'DATABASE F&B'!$C$3:$F$216,2,0) -> 0 | AD18: 1 | AE18: =VLOOKUP(AB18,'DATABASE F&B'!$C$3:$F$216,4,0) -> 0 | AF18: =AD18*AE18 -> 0 | AH18: =VLOOKUP(AG18,'DATABASE F&B'!$C$3:$F$216,2,0) -> 0 | AI18: 1 | AJ18: =VLOOKUP(AG18,'DATABASE F&B'!$C$3:$F$216,4,0) -> 0 | AK18: =AI18*AJ18 -> 0 | AM18: =VLOOKUP(AL18,'DATABASE F&B'!$C$3:$F$216,2,0) -> 0 | AN18: 1 | AO18: =VLOOKUP(AL18,'DATABASE F&B'!$C$3:$F$216,4,0) -> 0 | AP18: =AN18*AO18 -> 0 | AR18: =VLOOKUP(AQ18,'DATABASE F&B'!$C$3:$F$216,2,0) -> 0 | AS18: 1 | AT18: =VLOOKUP(AQ18,'DATABASE F&B'!$C$3:$F$216,4,0) -> 0 | AU18: =AS18*AT18 -> 0 | AW18: =VLOOKUP(AV18,'DATABASE F&B'!$C$3:$F$216,2,0) -> 0 | AY18: =VLOOKUP(AV18,'DATABASE F&B'!$C$3:$F$216,4,0) -> 0 | AZ18: =AX18*AY18 -> 0 | BB18: =VLOOKUP(BA18,'DATABASE F&B'!$C$3:$F$216,2,0) -> 0 | BD18: =VLOOKUP(BA18,'DATABASE F&B'!$C$3:$F$216,4,0) -> 0 | BE18: =BC18*BD18 -> 0 | BG18: =VLOOKUP(BF18,'DATABASE F&B'!$C$3:$F$216,2,0) -> 0 | BI18: =VLOOKUP(BF18,'DATABASE F&B'!$C$3:$F$216,4,0) -> 0 | BJ18: =BH18*BI18 -> 0 | BL18: =VLOOKUP(BK18,'DATABASE F&B'!$C$3:$F$210,2,0) -> 0 | BN18: =VLOOKUP(BK18,'DATABASE F&B'!$C$3:$F$210,4,0) -> 0 | BO18: =BM18*BN18 -> 0 | BQ18: =VLOOKUP(BP18,'DATABASE F&B'!$C$3:$F$210,2,0) -> 0 | BS18: =VLOOKUP(BP18,'DATABASE F&B'!$C$3:$F$210,4,0) -> 0 | BT18: =BR18*BS18 -> 0 | BV18: =VLOOKUP(BU18,'DATABASE F&B'!$C$3:$F$210,2,0) -> 0 | BX18: =VLOOKUP(BU18,'DATABASE F&B'!$C$3:$F$210,4,0) -> 0 | BY18: =BW18*BX18 -> 0 | CA18: =VLOOKUP(BZ18,'DATABASE F&B'!$C$3:$F$210,2,0) -> 0 | CC18: =VLOOKUP(BZ18,'DATABASE F&B'!$C$3:$F$210,4,0) -> 0 | CD18: =CB18*CC18 -> 0
A19: =CONCATENATE(F19,"-",E19,"-20",G19) -> 05-'03-2026 | B19: =B18+1 -> 15 | C19: =C18+1 -> 15 | D19: 46145 | E19: '03 | F19: 05 | G19: 26 | H19: =CONCATENATE("RJ","-",E19,F19,G19,"-",B19) -> RJ-'030526-15 | I19: =CONCATENATE(E19,"-",F19,"-20",G19) -> '03-05-2026 | J19: =VLOOKUP(D19,Laporan!$C$4:$D$34,2,0) -> Minggu | L19: Bar | M19: =SUMIF('DATABASE Room'!$B$3:$B$7,L19,'DATABASE Room'!$D$3:$D$7) -> 0 | N19: 1 | O19: =N19*M19 -> 0 | Q19: =P19*M19 -> 0 | R19: =O19+Q19 -> 0 | S19: =SUMIF($W$4:$CD$4,$S$4,W19:CD19) -> 5 | T19: =SUMIF($W$4:$CD$4,$T$4,W19:CD19) -> 41000 | U19: =R19+T19 -> 41000 | W19: 27 | X19: =VLOOKUP(W19,'DATABASE F&B'!$C$3:$F$216,2,0) -> KWETIEW SIRAM SAPI JAHE | Y19: 1 | Z19: =VLOOKUP(W19,'DATABASE F&B'!$C$3:$F$216,4,0) -> 41000 | AA19: =Y19*Z19 -> 41000 | AC19: =VLOOKUP(AB19,'DATABASE F&B'!$C$3:$F$216,2,0) -> 0 | AD19: 1 | AE19: =VLOOKUP(AB19,'DATABASE F&B'!$C$3:$F$216,4,0) -> 0 | AF19: =AD19*AE19 -> 0 | AH19: =VLOOKUP(AG19,'DATABASE F&B'!$C$3:$F$216,2,0) -> 0 | AI19: 1 | AJ19: =VLOOKUP(AG19,'DATABASE F&B'!$C$3:$F$216,4,0) -> 0 | AK19: =AI19*AJ19 -> 0 | AM19: =VLOOKUP(AL19,'DATABASE F&B'!$C$3:$F$216,2,0) -> 0 | AN19: 1 | AO19: =VLOOKUP(AL19,'DATABASE F&B'!$C$3:$F$216,4,0) -> 0 | AP19: =AN19*AO19 -> 0 | AR19: =VLOOKUP(AQ19,'DATABASE F&B'!$C$3:$F$216,2,0) -> 0 | AS19: 1 | AT19: =VLOOKUP(AQ19,'DATABASE F&B'!$C$3:$F$216,4,0) -> 0 | AU19: =AS19*AT19 -> 0 | AW19: =VLOOKUP(AV19,'DATABASE F&B'!$C$3:$F$216,2,0) -> 0 | AY19: =VLOOKUP(AV19,'DATABASE F&B'!$C$3:$F$216,4,0) -> 0 | AZ19: =AX19*AY19 -> 0 | BB19: =VLOOKUP(BA19,'DATABASE F&B'!$C$3:$F$216,2,0) -> 0 | BD19: =VLOOKUP(BA19,'DATABASE F&B'!$C$3:$F$216,4,0) -> 0 | BE19: =BC19*BD19 -> 0 | BG19: =VLOOKUP(BF19,'DATABASE F&B'!$C$3:$F$216,2,0) -> 0 | BI19: =VLOOKUP(BF19,'DATABASE F&B'!$C$3:$F$216,4,0) -> 0 | BJ19: =BH19*BI19 -> 0 | BL19: =VLOOKUP(BK19,'DATABASE F&B'!$C$3:$F$210,2,0) -> 0 | BN19: =VLOOKUP(BK19,'DATABASE F&B'!$C$3:$F$210,4,0) -> 0 | BO19: =BM19*BN19 -> 0 | BQ19: =VLOOKUP(BP19,'DATABASE F&B'!$C$3:$F$210,2,0) -> 0 | BS19: =VLOOKUP(BP19,'DATABASE F&B'!$C$3:$F$210,4,0) -> 0 | BT19: =BR19*BS19 -> 0 | BV19: =VLOOKUP(BU19,'DATABASE F&B'!$C$3:$F$210,2,0) -> 0 | BX19: =VLOOKUP(BU19,'DATABASE F&B'!$C$3:$F$210,4,0) -> 0 | BY19: =BW19*BX19 -> 0 | CA19: =VLOOKUP(BZ19,'DATABASE F&B'!$C$3:$F$210,2,0) -> 0 | CC19: =VLOOKUP(BZ19,'DATABASE F&B'!$C$3:$F$210,4,0) -> 0 | CD19: =CB19*CC19 -> 0
A20: =CONCATENATE(F20,"-",E20,"-20",G20) -> 05-'03-2026 | B20: =B19+1 -> 16 | C20: =C19+1 -> 16 | D20: 46145 | E20: '03 | F20: 05 | G20: 26 | H20: =CONCATENATE("RJ","-",E20,F20,G20,"-",B20) -> RJ-'030526-16 | I20: =CONCATENATE(E20,"-",F20,"-20",G20) -> '03-05-2026 | J20: =VLOOKUP(D20,Laporan!$C$4:$D$34,2,0) -> Minggu | L20: Bar | M20: =SUMIF('DATABASE Room'!$B$3:$B$7,L20,'DATABASE Room'!$D$3:$D$7) -> 0 | N20: 1 | O20: =N20*M20 -> 0 | Q20: =P20*M20 -> 0 | R20: =O20+Q20 -> 0 | S20: =SUMIF($W$4:$CD$4,$S$4,W20:CD20) -> 5 | T20: =SUMIF($W$4:$CD$4,$T$4,W20:CD20) -> 96000 | U20: =R20+T20 -> 96000 | W20: 28 | X20: =VLOOKUP(W20,'DATABASE F&B'!$C$3:$F$216,2,0) -> CHICKEN BULDAK | Y20: 1 | Z20: =VLOOKUP(W20,'DATABASE F&B'!$C$3:$F$216,4,0) -> 36000 | AA20: =Y20*Z20 -> 36000 | AB20: 75 | AC20: =VLOOKUP(AB20,'DATABASE F&B'!$C$3:$F$216,2,0) -> BEER KURA KURA EASY ALE | AD20: 1 | AE20: =VLOOKUP(AB20,'DATABASE F&B'!$C$3:$F$216,4,0) -> 60000 | AF20: =AD20*AE20 -> 60000 | AH20: =VLOOKUP(AG20,'DATABASE F&B'!$C$3:$F$216,2,0) -> 0 | AI20: 1 | AJ20: =VLOOKUP(AG20,'DATABASE F&B'!$C$3:$F$216,4,0) -> 0 | AK20: =AI20*AJ20 -> 0 | AM20: =VLOOKUP(AL20,'DATABASE F&B'!$C$3:$F$216,2,0) -> 0 | AN20: 1 | AO20: =VLOOKUP(AL20,'DATABASE F&B'!$C$3:$F$216,4,0) -> 0 | AP20: =AN20*AO20 -> 0 | AR20: =VLOOKUP(AQ20,'DATABASE F&B'!$C$3:$F$216,2,0) -> 0 | AS20: 1 | AT20: =VLOOKUP(AQ20,'DATABASE F&B'!$C$3:$F$216,4,0) -> 0 | AU20: =AS20*AT20 -> 0 | AW20: =VLOOKUP(AV20,'DATABASE F&B'!$C$3:$F$216,2,0) -> 0 | AY20: =VLOOKUP(AV20,'DATABASE F&B'!$C$3:$F$216,4,0) -> 0 | AZ20: =AX20*AY20 -> 0 | BB20: =VLOOKUP(BA20,'DATABASE F&B'!$C$3:$F$216,2,0) -> 0 | BD20: =VLOOKUP(BA20,'DATABASE F&B'!$C$3:$F$216,4,0) -> 0 | BE20: =BC20*BD20 -> 0 | BG20: =VLOOKUP(BF20,'DATABASE F&B'!$C$3:$F$216,2,0) -> 0 | BI20: =VLOOKUP(BF20,'DATABASE F&B'!$C$3:$F$216,4,0) -> 0 | BJ20: =BH20*BI20 -> 0 | BL20: =VLOOKUP(BK20,'DATABASE F&B'!$C$3:$F$210,2,0) -> 0 | BN20: =VLOOKUP(BK20,'DATABASE F&B'!$C$3:$F$210,4,0) -> 0 | BO20: =BM20*BN20 -> 0 | BQ20: =VLOOKUP(BP20,'DATABASE F&B'!$C$3:$F$210,2,0) -> 0 | BS20: =VLOOKUP(BP20,'DATABASE F&B'!$C$3:$F$210,4,0) -> 0 | BT20: =BR20*BS20 -> 0 | BV20: =VLOOKUP(BU20,'DATABASE F&B'!$C$3:$F$210,2,0) -> 0 | BX20: =VLOOKUP(BU20,'DATABASE F&B'!$C$3:$F$210,4,0) -> 0 | BY20: =BW20*BX20 -> 0 | CA20: =VLOOKUP(BZ20,'DATABASE F&B'!$C$3:$F$210,2,0) -> 0 | CC20: =VLOOKUP(BZ20,'DATABASE F&B'!$C$3:$F$210,4,0) -> 0 | CD20: =CB20*CC20 -> 0
A21: =CONCATENATE(F21,"-",E21,"-20",G21) -> 05-'03-2026 | B21: =B20+1 -> 17 | C21: =C20+1 -> 17 | D21: 46145 | E21: '03 | F21: 05 | G21: 26 | H21: =CONCATENATE("RJ","-",E21,F21,G21,"-",B21) -> RJ-'030526-17 | I21: =CONCATENATE(E21,"-",F21,"-20",G21) -> '03-05-2026 | J21: =VLOOKUP(D21,Laporan!$C$4:$D$34,2,0) -> Minggu | L21: Bar | M21: =SUMIF('DATABASE Room'!$B$3:$B$7,L21,'DATABASE Room'!$D$3:$D$7) -> 0 | N21: 1 | O21: =N21*M21 -> 0 | Q21: =P21*M21 -> 0 | R21: =O21+Q21 -> 0 | S21: =SUMIF($W$4:$CD$4,$S$4,W21:CD21) -> 5 | T21: =SUMIF($W$4:$CD$4,$T$4,W21:CD21) -> 10000 | U21: =R21+T21 -> 10000 | W21: 29 | X21: =VLOOKUP(W21,'DATABASE F&B'!$C$3:$F$216,2,0) -> STEAM RICE | Y21: 1 | Z21: =VLOOKUP(W21,'DATABASE F&B'!$C$3:$F$216,4,0) -> 10000 | AA21: =Y21*Z21 -> 10000 | AC21: =VLOOKUP(AB21,'DATABASE F&B'!$C$3:$F$216,2,0) -> 0 | AD21: 1 | AE21: =VLOOKUP(AB21,'DATABASE F&B'!$C$3:$F$216,4,0) -> 0 | AF21: =AD21*AE21 -> 0 | AH21: =VLOOKUP(AG21,'DATABASE F&B'!$C$3:$F$216,2,0) -> 0 | AI21: 1 | AJ21: =VLOOKUP(AG21,'DATABASE F&B'!$C$3:$F$216,4,0) -> 0 | AK21: =AI21*AJ21 -> 0 | AM21: =VLOOKUP(AL21,'DATABASE F&B'!$C$3:$F$216,2,0) -> 0 | AN21: 1 | AO21: =VLOOKUP(AL21,'DATABASE F&B'!$C$3:$F$216,4,0) -> 0 | AP21: =AN21*AO21 -> 0 | AR21: =VLOOKUP(AQ21,'DATABASE F&B'!$C$3:$F$216,2,0) -> 0 | AS21: 1 | AT21: =VLOOKUP(AQ21,'DATABASE F&B'!$C$3:$F$216,4,0) -> 0 | AU21: =AS21*AT21 -> 0 | AW21: =VLOOKUP(AV21,'DATABASE F&B'!$C$3:$F$216,2,0) -> 0 | AY21: =VLOOKUP(AV21,'DATABASE F&B'!$C$3:$F$216,4,0) -> 0 | AZ21: =AX21*AY21 -> 0 | BB21: =VLOOKUP(BA21,'DATABASE F&B'!$C$3:$F$216,2,0) -> 0 | BD21: =VLOOKUP(BA21,'DATABASE F&B'!$C$3:$F$216,4,0) -> 0 | BE21: =BC21*BD21 -> 0 | BG21: =VLOOKUP(BF21,'DATABASE F&B'!$C$3:$F$216,2,0) -> 0 | BI21: =VLOOKUP(BF21,'DATABASE F&B'!$C$3:$F$216,4,0) -> 0 | BJ21: =BH21*BI21 -> 0 | BL21: =VLOOKUP(BK21,'DATABASE F&B'!$C$3:$F$210,2,0) -> 0 | BN21: =VLOOKUP(BK21,'DATABASE F&B'!$C$3:$F$210,4,0) -> 0 | BO21: =BM21*BN21 -> 0 | BQ21: =VLOOKUP(BP21,'DATABASE F&B'!$C$3:$F$210,2,0) -> 0 | BS21: =VLOOKUP(BP21,'DATABASE F&B'!$C$3:$F$210,4,0) -> 0 | BT21: =BR21*BS21 -> 0 | BV21: =VLOOKUP(BU21,'DATABASE F&B'!$C$3:$F$210,2,0) -> 0 | BX21: =VLOOKUP(BU21,'DATABASE F&B'!$C$3:$F$210,4,0) -> 0 | BY21: =BW21*BX21 -> 0 | CA21: =VLOOKUP(BZ21,'DATABASE F&B'!$C$3:$F$210,2,0) -> 0 | CC21: =VLOOKUP(BZ21,'DATABASE F&B'!$C$3:$F$210,4,0) -> 0 | CD21: =CB21*CC21 -> 0
A22: =CONCATENATE(F22,"-",E22,"-20",G22) -> 05-'03-2026 | B22: =B21+1 -> 18 | C22: =C21+1 -> 18 | D22: 46145 | E22: '03 | F22: 05 | G22: 26 | H22: =CONCATENATE("RJ","-",E22,F22,G22,"-",B22) -> RJ-'030526-18 | I22: =CONCATENATE(E22,"-",F22,"-20",G22) -> '03-05-2026 | J22: =VLOOKUP(D22,Laporan!$C$4:$D$34,2,0) -> Minggu | L22: Bar | M22: =SUMIF('DATABASE Room'!$B$3:$B$7,L22,'DATABASE Room'!$D$3:$D$7) -> 0 | N22: 1 | O22: =N22*M22 -> 0 | Q22: =P22*M22 -> 0 | R22: =O22+Q22 -> 0 | S22: =SUMIF($W$4:$CD$4,$S$4,W22:CD22) -> 5 | T22: =SUMIF($W$4:$CD$4,$T$4,W22:CD22) -> 23000 | U22: =R22+T22 -> 23000 | W22: 30 | X22: =VLOOKUP(W22,'DATABASE F&B'!$C$3:$F$216,2,0) -> MENDOAN | Y22: 1 | Z22: =VLOOKUP(W22,'DATABASE F&B'!$C$3:$F$216,4,0) -> 23000 | AA22: =Y22*Z22 -> 23000 | AC22: =VLOOKUP(AB22,'DATABASE F&B'!$C$3:$F$216,2,0) -> 0 | AD22: 1 | AE22: =VLOOKUP(AB22,'DATABASE F&B'!$C$3:$F$216,4,0) -> 0 | AF22: =AD22*AE22 -> 0 | AH22: =VLOOKUP(AG22,'DATABASE F&B'!$C$3:$F$216,2,0) -> 0 | AI22: 1 | AJ22: =VLOOKUP(AG22,'DATABASE F&B'!$C$3:$F$216,4,0) -> 0 | AK22: =AI22*AJ22 -> 0 | AM22: =VLOOKUP(AL22,'DATABASE F&B'!$C$3:$F$216,2,0) -> 0 | AN22: 1 | AO22: =VLOOKUP(AL22,'DATABASE F&B'!$C$3:$F$216,4,0) -> 0 | AP22: =AN22*AO22 -> 0 | AR22: =VLOOKUP(AQ22,'DATABASE F&B'!$C$3:$F$216,2,0) -> 0 | AS22: 1 | AT22: =VLOOKUP(AQ22,'DATABASE F&B'!$C$3:$F$216,4,0) -> 0 | AU22: =AS22*AT22 -> 0 | AW22: =VLOOKUP(AV22,'DATABASE F&B'!$C$3:$F$216,2,0) -> 0 | AY22: =VLOOKUP(AV22,'DATABASE F&B'!$C$3:$F$216,4,0) -> 0 | AZ22: =AX22*AY22 -> 0 | BB22: =VLOOKUP(BA22,'DATABASE F&B'!$C$3:$F$216,2,0) -> 0 | BD22: =VLOOKUP(BA22,'DATABASE F&B'!$C$3:$F$216,4,0) -> 0 | BE22: =BC22*BD22 -> 0 | BG22: =VLOOKUP(BF22,'DATABASE F&B'!$C$3:$F$216,2,0) -> 0 | BI22: =VLOOKUP(BF22,'DATABASE F&B'!$C$3:$F$216,4,0) -> 0 | BJ22: =BH22*BI22 -> 0 | BL22: =VLOOKUP(BK22,'DATABASE F&B'!$C$3:$F$210,2,0) -> 0 | BN22: =VLOOKUP(BK22,'DATABASE F&B'!$C$3:$F$210,4,0) -> 0 | BO22: =BM22*BN22 -> 0 | BQ22: =VLOOKUP(BP22,'DATABASE F&B'!$C$3:$F$210,2,0) -> 0 | BS22: =VLOOKUP(BP22,'DATABASE F&B'!$C$3:$F$210,4,0) -> 0 | BT22: =BR22*BS22 -> 0 | BV22: =VLOOKUP(BU22,'DATABASE F&B'!$C$3:$F$210,2,0) -> 0 | BX22: =VLOOKUP(BU22,'DATABASE F&B'!$C$3:$F$210,4,0) -> 0 | BY22: =BW22*BX22 -> 0 | CA22: =VLOOKUP(BZ22,'DATABASE F&B'!$C$3:$F$210,2,0) -> 0 | CC22: =VLOOKUP(BZ22,'DATABASE F&B'!$C$3:$F$210,4,0) -> 0 | CD22: =CB22*CC22 -> 0
A23: =CONCATENATE(F23,"-",E23,"-20",G23) -> 05-'04-2026 | B23: =B22+1 -> 19 | C23: =C22+1 -> 19 | D23: 46146 | E23: '04 | F23: 05 | G23: 26 | H23: =CONCATENATE("RJ","-",E23,F23,G23,"-",B23) -> RJ-'040526-19 | I23: =CONCATENATE(E23,"-",F23,"-20",G23) -> '04-05-2026 | J23: =VLOOKUP(D23,Laporan!$C$4:$D$34,2,0) -> Senin | L23: Bar | M23: =SUMIF('DATABASE Room'!$B$3:$B$7,L23,'DATABASE Room'!$D$3:$D$7) -> 0 | N23: 1 | O23: =N23*M23 -> 0 | Q23: =P23*M23 -> 0 | R23: =O23+Q23 -> 0 | S23: =SUMIF($W$4:$CD$4,$S$4,W23:CD23) -> 5 | T23: =SUMIF($W$4:$CD$4,$T$4,W23:CD23) -> 38000 | U23: =R23+T23 -> 38000 | W23: 31 | X23: =VLOOKUP(W23,'DATABASE F&B'!$C$3:$F$216,2,0) -> NASI GORENG DAGING ASAP | Y23: 1 | Z23: =VLOOKUP(W23,'DATABASE F&B'!$C$3:$F$216,4,0) -> 38000 | AA23: =Y23*Z23 -> 38000 | AC23: =VLOOKUP(AB23,'DATABASE F&B'!$C$3:$F$216,2,0) -> 0 | AD23: 1 | AE23: =VLOOKUP(AB23,'DATABASE F&B'!$C$3:$F$216,4,0) -> 0 | AF23: =AD23*AE23 -> 0 | AH23: =VLOOKUP(AG23,'DATABASE F&B'!$C$3:$F$216,2,0) -> 0 | AI23: 1 | AJ23: =VLOOKUP(AG23,'DATABASE F&B'!$C$3:$F$216,4,0) -> 0 | AK23: =AI23*AJ23 -> 0 | AM23: =VLOOKUP(AL23,'DATABASE F&B'!$C$3:$F$216,2,0) -> 0 | AN23: 1 | AO23: =VLOOKUP(AL23,'DATABASE F&B'!$C$3:$F$216,4,0) -> 0 | AP23: =AN23*AO23 -> 0 | AR23: =VLOOKUP(AQ23,'DATABASE F&B'!$C$3:$F$216,2,0) -> 0 | AS23: 1 | AT23: =VLOOKUP(AQ23,'DATABASE F&B'!$C$3:$F$216,4,0) -> 0 | AU23: =AS23*AT23 -> 0 | AW23: =VLOOKUP(AV23,'DATABASE F&B'!$C$3:$F$216,2,0) -> 0 | AY23: =VLOOKUP(AV23,'DATABASE F&B'!$C$3:$F$216,4,0) -> 0 | AZ23: =AX23*AY23 -> 0 | BB23: =VLOOKUP(BA23,'DATABASE F&B'!$C$3:$F$216,2,0) -> 0 | BD23: =VLOOKUP(BA23,'DATABASE F&B'!$C$3:$F$216,4,0) -> 0 | BE23: =BC23*BD23 -> 0 | BG23: =VLOOKUP(BF23,'DATABASE F&B'!$C$3:$F$216,2,0) -> 0 | BI23: =VLOOKUP(BF23,'DATABASE F&B'!$C$3:$F$216,4,0) -> 0 | BJ23: =BH23*BI23 -> 0 | BL23: =VLOOKUP(BK23,'DATABASE F&B'!$C$3:$F$210,2,0) -> 0 | BN23: =VLOOKUP(BK23,'DATABASE F&B'!$C$3:$F$210,4,0) -> 0 | BO23: =BM23*BN23 -> 0 | BQ23: =VLOOKUP(BP23,'DATABASE F&B'!$C$3:$F$210,2,0) -> 0 | BS23: =VLOOKUP(BP23,'DATABASE F&B'!$C$3:$F$210,4,0) -> 0 | BT23: =BR23*BS23 -> 0 | BV23: =VLOOKUP(BU23,'DATABASE F&B'!$C$3:$F$210,2,0) -> 0 | BX23: =VLOOKUP(BU23,'DATABASE F&B'!$C$3:$F$210,4,0) -> 0 | BY23: =BW23*BX23 -> 0 | CA23: =VLOOKUP(BZ23,'DATABASE F&B'!$C$3:$F$210,2,0) -> 0 | CC23: =VLOOKUP(BZ23,'DATABASE F&B'!$C$3:$F$210,4,0) -> 0 | CD23: =CB23*CC23 -> 0
A24: =CONCATENATE(F24,"-",E24,"-20",G24) -> 05-'04-2026 | B24: =B23+1 -> 20 | C24: =C23+1 -> 20 | D24: 46146 | E24: '04 | F24: 05 | G24: 26 | H24: =CONCATENATE("RJ","-",E24,F24,G24,"-",B24) -> RJ-'040526-20 | I24: =CONCATENATE(E24,"-",F24,"-20",G24) -> '04-05-2026 | J24: =VLOOKUP(D24,Laporan!$C$4:$D$34,2,0) -> Senin | L24: Bar | M24: =SUMIF('DATABASE Room'!$B$3:$B$7,L24,'DATABASE Room'!$D$3:$D$7) -> 0 | N24: 1 | O24: =N24*M24 -> 0 | Q24: =P24*M24 -> 0 | R24: =O24+Q24 -> 0 | S24: =SUMIF($W$4:$CD$4,$S$4,W24:CD24) -> 5 | T24: =SUMIF($W$4:$CD$4,$T$4,W24:CD24) -> 565000 | U24: =R24+T24 -> 565000 | W24: 47 | X24: =VLOOKUP(W24,'DATABASE F&B'!$C$3:$F$216,2,0) -> PULPY ORANGE 300ML | Y24: 1 | Z24: =VLOOKUP(W24,'DATABASE F&B'!$C$3:$F$216,4,0) -> 15000 | AA24: =Y24*Z24 -> 15000 | AB24: 110 | AC24: =VLOOKUP(AB24,'DATABASE F&B'!$C$3:$F$216,2,0) -> JAGERMEISTER 700ML | AD24: 1 | AE24: =VLOOKUP(AB24,'DATABASE F&B'!$C$3:$F$216,4,0) -> 550000 | AF24: =AD24*AE24 -> 550000 | AH24: =VLOOKUP(AG24,'DATABASE F&B'!$C$3:$F$216,2,0) -> 0 | AI24: 1 | AJ24: =VLOOKUP(AG24,'DATABASE F&B'!$C$3:$F$216,4,0) -> 0 | AK24: =AI24*AJ24 -> 0 | AM24: =VLOOKUP(AL24,'DATABASE F&B'!$C$3:$F$216,2,0) -> 0 | AN24: 1 | AO24: =VLOOKUP(AL24,'DATABASE F&B'!$C$3:$F$216,4,0) -> 0 | AP24: =AN24*AO24 -> 0 | AR24: =VLOOKUP(AQ24,'DATABASE F&B'!$C$3:$F$216,2,0) -> 0 | AS24: 1 | AT24: =VLOOKUP(AQ24,'DATABASE F&B'!$C$3:$F$216,4,0) -> 0 | AU24: =AS24*AT24 -> 0 | AW24: =VLOOKUP(AV24,'DATABASE F&B'!$C$3:$F$216,2,0) -> 0 | AY24: =VLOOKUP(AV24,'DATABASE F&B'!$C$3:$F$216,4,0) -> 0 | AZ24: =AX24*AY24 -> 0 | BB24: =VLOOKUP(BA24,'DATABASE F&B'!$C$3:$F$216,2,0) -> 0 | BD24: =VLOOKUP(BA24,'DATABASE F&B'!$C$3:$F$216,4,0) -> 0 | BE24: =BC24*BD24 -> 0 | BG24: =VLOOKUP(BF24,'DATABASE F&B'!$C$3:$F$216,2,0) -> 0 | BI24: =VLOOKUP(BF24,'DATABASE F&B'!$C$3:$F$216,4,0) -> 0 | BJ24: =BH24*BI24 -> 0 | BL24: =VLOOKUP(BK24,'DATABASE F&B'!$C$3:$F$210,2,0) -> 0 | BN24: =VLOOKUP(BK24,'DATABASE F&B'!$C$3:$F$210,4,0) -> 0 | BO24: =BM24*BN24 -> 0 | BQ24: =VLOOKUP(BP24,'DATABASE F&B'!$C$3:$F$210,2,0) -> 0 | BS24: =VLOOKUP(BP24,'DATABASE F&B'!$C$3:$F$210,4,0) -> 0 | BT24: =BR24*BS24 -> 0 | BV24: =VLOOKUP(BU24,'DATABASE F&B'!$C$3:$F$210,2,0) -> 0 | BX24: =VLOOKUP(BU24,'DATABASE F&B'!$C$3:$F$210,4,0) -> 0 | BY24: =BW24*BX24 -> 0 | CA24: =VLOOKUP(BZ24,'DATABASE F&B'!$C$3:$F$210,2,0) -> 0 | CC24: =VLOOKUP(BZ24,'DATABASE F&B'!$C$3:$F$210,4,0) -> 0 | CD24: =CB24*CC24 -> 0
A25: =CONCATENATE(F25,"-",E25,"-20",G25) -> 05-'04-2026 | B25: =B24+1 -> 21 | C25: =C24+1 -> 21 | D25: 46146 | E25: '04 | F25: 05 | G25: 26 | H25: =CONCATENATE("RJ","-",E25,F25,G25,"-",B25) -> RJ-'040526-21 | I25: =CONCATENATE(E25,"-",F25,"-20",G25) -> '04-05-2026 | J25: =VLOOKUP(D25,Laporan!$C$4:$D$34,2,0) -> Senin | L25: Bar | M25: =SUMIF('DATABASE Room'!$B$3:$B$7,L25,'DATABASE Room'!$D$3:$D$7) -> 0 | N25: 1 | O25: =N25*M25 -> 0 | Q25: =P25*M25 -> 0 | R25: =O25+Q25 -> 0 | S25: =SUMIF($W$4:$CD$4,$S$4,W25:CD25) -> 5 | T25: =SUMIF($W$4:$CD$4,$T$4,W25:CD25) -> 8000 | U25: =R25+T25 -> 8000 | W25: 45 | X25: =VLOOKUP(W25,'DATABASE F&B'!$C$3:$F$216,2,0) -> LE MINERAL 330ML | Y25: 1 | Z25: =VLOOKUP(W25,'DATABASE F&B'!$C$3:$F$216,4,0) -> 8000 | AA25: =Y25*Z25 -> 8000 | AC25: =VLOOKUP(AB25,'DATABASE F&B'!$C$3:$F$216,2,0) -> 0 | AD25: 1 | AE25: =VLOOKUP(AB25,'DATABASE F&B'!$C$3:$F$216,4,0) -> 0 | AF25: =AD25*AE25 -> 0 | AH25: =VLOOKUP(AG25,'DATABASE F&B'!$C$3:$F$216,2,0) -> 0 | AI25: 1 | AJ25: =VLOOKUP(AG25,'DATABASE F&B'!$C$3:$F$216,4,0) -> 0 | AK25: =AI25*AJ25 -> 0 | AM25: =VLOOKUP(AL25,'DATABASE F&B'!$C$3:$F$216,2,0) -> 0 | AN25: 1 | AO25: =VLOOKUP(AL25,'DATABASE F&B'!$C$3:$F$216,4,0) -> 0 | AP25: =AN25*AO25 -> 0 | AR25: =VLOOKUP(AQ25,'DATABASE F&B'!$C$3:$F$216,2,0) -> 0 | AS25: 1 | AT25: =VLOOKUP(AQ25,'DATABASE F&B'!$C$3:$F$216,4,0) -> 0 | AU25: =AS25*AT25 -> 0 | AW25: =VLOOKUP(AV25,'DATABASE F&B'!$C$3:$F$216,2,0) -> 0 | AY25: =VLOOKUP(AV25,'DATABASE F&B'!$C$3:$F$216,4,0) -> 0 | AZ25: =AX25*AY25 -> 0 | BB25: =VLOOKUP(BA25,'DATABASE F&B'!$C$3:$F$216,2,0) -> 0 | BD25: =VLOOKUP(BA25,'DATABASE F&B'!$C$3:$F$216,4,0) -> 0 | BE25: =BC25*BD25 -> 0 | BG25: =VLOOKUP(BF25,'DATABASE F&B'!$C$3:$F$216,2,0) -> 0 | BI25: =VLOOKUP(BF25,'DATABASE F&B'!$C$3:$F$216,4,0) -> 0 | BJ25: =BH25*BI25 -> 0 | BL25: =VLOOKUP(BK25,'DATABASE F&B'!$C$3:$F$210,2,0) -> 0 | BN25: =VLOOKUP(BK25,'DATABASE F&B'!$C$3:$F$210,4,0) -> 0 | BO25: =BM25*BN25 -> 0 | BQ25: =VLOOKUP(BP25,'DATABASE F&B'!$C$3:$F$210,2,0) -> 0 | BS25: =VLOOKUP(BP25,'DATABASE F&B'!$C$3:$F$210,4,0) -> 0 | BT25: =BR25*BS25 -> 0 | BV25: =VLOOKUP(BU25,'DATABASE F&B'!$C$3:$F$210,2,0) -> 0 | BX25: =VLOOKUP(BU25,'DATABASE F&B'!$C$3:$F$210,4,0) -> 0 | BY25: =BW25*BX25 -> 0 | CA25: =VLOOKUP(BZ25,'DATABASE F&B'!$C$3:$F$210,2,0) -> 0 | CC25: =VLOOKUP(BZ25,'DATABASE F&B'!$C$3:$F$210,4,0) -> 0 | CD25: =CB25*CC25 -> 0
A26: =CONCATENATE(F26,"-",E26,"-20",G26) -> 05-'04-2026 | B26: =B25+1 -> 22 | C26: =C25+1 -> 22 | D26: 46146 | E26: '04 | F26: 05 | G26: 26 | H26: =CONCATENATE("RJ","-",E26,F26,G26,"-",B26) -> RJ-'040526-22 | I26: =CONCATENATE(E26,"-",F26,"-20",G26) -> '04-05-2026 | J26: =VLOOKUP(D26,Laporan!$C$4:$D$34,2,0) -> Senin | L26: Bar | M26: =SUMIF('DATABASE Room'!$B$3:$B$7,L26,'DATABASE Room'!$D$3:$D$7) -> 0 | N26: 1 | O26: =N26*M26 -> 0 | Q26: =P26*M26 -> 0 | R26: =O26+Q26 -> 0 | S26: =SUMIF($W$4:$CD$4,$S$4,W26:CD26) -> 5 | T26: =SUMIF($W$4:$CD$4,$T$4,W26:CD26) -> 15000 | U26: =R26+T26 -> 15000 | W26: 46 | X26: =VLOOKUP(W26,'DATABASE F&B'!$C$3:$F$216,2,0) -> TEH PUCUK HARUM 350ML | Y26: 1 | Z26: =VLOOKUP(W26,'DATABASE F&B'!$C$3:$F$216,4,0) -> 15000 | AA26: =Y26*Z26 -> 15000 | AC26: =VLOOKUP(AB26,'DATABASE F&B'!$C$3:$F$216,2,0) -> 0 | AD26: 1 | AE26: =VLOOKUP(AB26,'DATABASE F&B'!$C$3:$F$216,4,0) -> 0 | AF26: =AD26*AE26 -> 0 | AH26: =VLOOKUP(AG26,'DATABASE F&B'!$C$3:$F$216,2,0) -> 0 | AI26: 1 | AJ26: =VLOOKUP(AG26,'DATABASE F&B'!$C$3:$F$216,4,0) -> 0 | AK26: =AI26*AJ26 -> 0 | AM26: =VLOOKUP(AL26,'DATABASE F&B'!$C$3:$F$216,2,0) -> 0 | AN26: 1 | AO26: =VLOOKUP(AL26,'DATABASE F&B'!$C$3:$F$216,4,0) -> 0 | AP26: =AN26*AO26 -> 0 | AR26: =VLOOKUP(AQ26,'DATABASE F&B'!$C$3:$F$216,2,0) -> 0 | AS26: 1 | AT26: =VLOOKUP(AQ26,'DATABASE F&B'!$C$3:$F$216,4,0) -> 0 | AU26: =AS26*AT26 -> 0 | AW26: =VLOOKUP(AV26,'DATABASE F&B'!$C$3:$F$216,2,0) -> 0 | AY26: =VLOOKUP(AV26,'DATABASE F&B'!$C$3:$F$216,4,0) -> 0 | AZ26: =AX26*AY26 -> 0 | BB26: =VLOOKUP(BA26,'DATABASE F&B'!$C$3:$F$216,2,0) -> 0 | BD26: =VLOOKUP(BA26,'DATABASE F&B'!$C$3:$F$216,4,0) -> 0 | BE26: =BC26*BD26 -> 0 | BG26: =VLOOKUP(BF26,'DATABASE F&B'!$C$3:$F$216,2,0) -> 0 | BI26: =VLOOKUP(BF26,'DATABASE F&B'!$C$3:$F$216,4,0) -> 0 | BJ26: =BH26*BI26 -> 0 | BL26: =VLOOKUP(BK26,'DATABASE F&B'!$C$3:$F$210,2,0) -> 0 | BN26: =VLOOKUP(BK26,'DATABASE F&B'!$C$3:$F$210,4,0) -> 0 | BO26: =BM26*BN26 -> 0 | BQ26: =VLOOKUP(BP26,'DATABASE F&B'!$C$3:$F$210,2,0) -> 0 | BS26: =VLOOKUP(BP26,'DATABASE F&B'!$C$3:$F$210,4,0) -> 0 | BT26: =BR26*BS26 -> 0 | BV26: =VLOOKUP(BU26,'DATABASE F&B'!$C$3:$F$210,2,0) -> 0 | BX26: =VLOOKUP(BU26,'DATABASE F&B'!$C$3:$F$210,4,0) -> 0 | BY26: =BW26*BX26 -> 0 | CA26: =VLOOKUP(BZ26,'DATABASE F&B'!$C$3:$F$210,2,0) -> 0 | CC26: =VLOOKUP(BZ26,'DATABASE F&B'!$C$3:$F$210,4,0) -> 0 | CD26: =CB26*CC26 -> 0
